[
    {
        "filename": "HADOOP-6989.json",
        "creation_time": "2010-10-04T23:55:16.000+0000",
        "bug_report": {
            "Title": "IllegalArgumentException in MapFile.Writer Initialization",
            "Description": "An IllegalArgumentException is thrown when attempting to initialize the MapFile.Writer due to missing key class or comparator option. This issue occurs during the execution of the TestSetFile test case.",
            "StackTrace": [
                "Caused by: java.lang.IllegalArgumentException: key class or comparator option must be set",
                "at org.apache.hadoop.io.MapFile$Writer.<init>(MapFile.java:247)",
                "at org.apache.hadoop.io.SetFile$Writer.<init>(SetFile.java:60)",
                "at org.apache.hadoop.io.TestSetFile.writeTest(TestSetFile.java:73)",
                "at org.apache.hadoop.io.TestSetFile.testSetFile(TestSetFile.java:45)"
            ],
            "RootCause": "The key class or comparator option was not set when initializing MapFile.Writer, which is mandatory for writing to a MapFile.",
            "StepsToReproduce": [
                "Run the TestSetFile test case.",
                "Ensure that the MapFile.Writer is initialized without setting the key class or comparator."
            ],
            "ExpectedBehavior": "The MapFile.Writer should initialize successfully with the appropriate key class or comparator set, allowing the test to proceed without exceptions.",
            "ObservedBehavior": "An IllegalArgumentException is thrown, indicating that the key class or comparator option must be set.",
            "Suggestions": "Review the initialization of MapFile.Writer in the TestSetFile class. Ensure that either the key class or comparator is set before the writer is instantiated. Update the test case to include these parameters."
        }
    },
    {
        "filename": "HADOOP-10823.json",
        "creation_time": "2014-07-15T07:20:00.000+0000",
        "bug_report": {
            "Title": "AssertionFailedError and EOFException in ReloadingX509TrustManager Tests",
            "Description": "The test case 'testReload' in the 'TestReloadingX509TrustManager' class is failing due to an AssertionFailedError, indicating a mismatch between expected and actual values. Additionally, an EOFException is thrown when attempting to load a KeyStore, suggesting potential corruption or formatting issues with the KeyStore file.",
            "StackTrace": [
                "junit.framework.AssertionFailedError: expected:<2> but was:<1>",
                "at junit.framework.Assert.fail(Assert.java:50)",
                "at junit.framework.Assert.failNotEquals(Assert.java:287)",
                "at junit.framework.Assert.assertEquals(Assert.java:67)",
                "at junit.framework.Assert.assertEquals(Assert.java:199)",
                "at junit.framework.Assert.assertEquals(Assert.java:205)",
                "at org.apache.hadoop.security.ssl.TestReloadingX509TrustManager.testReload(TestReloadingX509TrustManager.java:112)",
                "java.io.EOFException",
                "at java.io.DataInputStream.readInt(DataInputStream.java:375)",
                "at sun.security.provider.JavaKeyStore.engineLoad(JavaKeyStore.java:628)",
                "at sun.security.provider.JavaKeyStore$JKS.engineLoad(JavaKeyStore.java:38)",
                "at java.security.KeyStore.load(KeyStore.java:1185)",
                "at org.apache.hadoop.security.ssl.ReloadingX509TrustManager.loadTrustManager(ReloadingX509TrustManager.java:166)",
                "at org.apache.hadoop.security.ssl.ReloadingX509TrustManager.run(ReloadingX509TrustManager.java:195)",
                "at java.lang.Thread.run(Thread.java:662)"
            ],
            "RootCause": "The AssertionFailedError indicates a logical error in the test case, while the EOFException suggests that the KeyStore file may be corrupted or improperly formatted.",
            "StepsToReproduce": [
                "Run the JUnit test suite that includes 'TestReloadingX509TrustManager'.",
                "Ensure that the KeyStore file used in the test is accessible and correctly formatted.",
                "Observe the output for AssertionFailedError and EOFException."
            ],
            "ExpectedBehavior": "The test should pass, confirming that the ReloadingX509TrustManager correctly loads the KeyStore and returns the expected value of '2'.",
            "ObservedBehavior": "The test fails with an AssertionFailedError indicating an expected value of '2' but received '1', and an EOFException occurs when attempting to load the KeyStore.",
            "Suggestions": "1. Verify the contents and format of the KeyStore file used in the test. Ensure it is not corrupted. 2. Review the logic in the 'testReload' method to ensure it correctly sets up the expected conditions for the test. 3. If the KeyStore is valid, investigate the implementation of the ReloadingX509TrustManager to ensure it correctly processes the KeyStore."
        }
    },
    {
        "filename": "HADOOP-9125.json",
        "creation_time": "2012-12-10T02:07:52.000+0000",
        "bug_report": {
            "Title": "LDAP Connection Closed Exception",
            "Description": "A CommunicationException is thrown during an LDAP search operation, indicating that the connection was unexpectedly closed. This issue arises when the application attempts to retrieve user group information from an LDAP server.",
            "StackTrace": [
                "javax.naming.CommunicationException: connection closed [Root exception is java.io.IOException: connection closed]; remaining name 'CN=Users,DC=EXAMPLE,DC=COM'",
                "at com.sun.jndi.ldap.LdapCtx.doSearch(LdapCtx.java:1983)",
                "at com.sun.jndi.ldap.LdapCtx.searchAux(LdapCtx.java:1827)",
                "at com.sun.jndi.ldap.LdapCtx.c_search(LdapCtx.java:1752)",
                "at com.sun.jndi.ldap.LdapCtx.c_search(LdapCtx.java:1769)",
                "at com.sun.jndi.toolkit.ctx.ComponentDirContext.p_search(ComponentDirContext.java:394)",
                "at com.sun.jndi.toolkit.ctx.PartialCompositeDirContext.search(PartialCompositeDirContext.java:376)",
                "at com.sun.jndi.toolkit.ctx.PartialCompositeDirContext.search(PartialCompositeDirContext.java:358)",
                "at javax.naming.directory.InitialDirContext.search(InitialDirContext.java:267)",
                "at org.apache.hadoop.security.LdapGroupsMapping.getGroups(LdapGroupsMapping.java:187)",
                "at org.apache.hadoop.security.CompositeGroupsMapping.getGroups(CompositeGroupsMapping.java:97)",
                "at org.apache.hadoop.security.Groups.doGetGroups(Groups.java:103)",
                "at org.apache.hadoop.security.Groups.getGroups(Groups.java:70)",
                "at org.apache.hadoop.security.UserGroupInformation.getGroupNames(UserGroupInformation.java:1035)",
                "at org.apache.hadoop.hbase.security.User.getGroupNames(User.java:90)",
                "at org.apache.hadoop.hbase.security.access.TableAuthManager.authorize(TableAuthManager.java:355)",
                "at org.apache.hadoop.hbase.security.access.AccessController.requirePermission(AccessController.java:379)",
                "at org.apache.hadoop.hbase.security.access.AccessController.getUserPermissions(AccessController.java:1051)",
                "at sun.reflect.NativeMethodAccessorImpl.invoke0(Native Method)",
                "at sun.reflect.NativeMethodAccessorImpl.invoke(NativeMethodAccessorImpl.java:39)",
                "at sun.reflect.DelegatingMethodAccessorImpl.invoke(DelegatingMethodAccessorImpl.java:25)",
                "at java.lang.reflect.Method.invoke(Method.java:597)",
                "at org.apache.hadoop.hbase.regionserver.HRegion.exec(HRegion.java:4914)",
                "at org.apache.hadoop.hbase.regionserver.HRegionServer.execCoprocessor(HRegionServer.java:3546)",
                "at sun.reflect.NativeMethodAccessorImpl.invoke0(Native Method)",
                "at sun.reflect.NativeMethodAccessorImpl.invoke(NativeMethodAccessorImpl.java:39)",
                "at sun.reflect.DelegatingMethodAccessorImpl.invoke(DelegatingMethodAccessorImpl.java:25)",
                "at java.lang.reflect.Method.invoke(Method.java:597)",
                "at org.apache.hadoop.hbase.ipc.SecureRpcEngine$Server.call(SecureRpcEngine.java:372)",
                "at org.apache.hadoop.hbase.ipc.HBaseServer$Handler.run(HBaseServer.java:1399)",
                "Caused by: java.io.IOException: connection closed",
                "at com.sun.jndi.ldap.LdapClient.ensureOpen(LdapClient.java:1558)",
                "at com.sun.jndi.ldap.LdapClient.search(LdapClient.java:503)",
                "at com.sun.jndi.ldap.LdapCtx.doSearch(LdapCtx.java:1965)"
            ],
            "RootCause": "The LDAP connection was closed unexpectedly, likely due to network issues, misconfiguration, or server-side constraints.",
            "StepsToReproduce": [
                "Attempt to perform an LDAP search operation using the application.",
                "Ensure the LDAP server is reachable and configured correctly.",
                "Monitor the network connection during the operation."
            ],
            "ExpectedBehavior": "The application should successfully retrieve user group information from the LDAP server without any exceptions.",
            "ObservedBehavior": "The application throws a CommunicationException indicating that the connection was closed during the LDAP search operation.",
            "Suggestions": "Check the LDAP server's status and configuration. Ensure that the network connection is stable and that there are no firewall rules blocking the connection. Review the LDAP client settings in the application for any misconfigurations."
        }
    },
    {
        "filename": "HADOOP-10252.json",
        "creation_time": "2014-01-22T16:43:27.000+0000",
        "bug_report": {
            "Title": "IllegalArgumentException due to null property value in Hadoop Configuration",
            "Description": "An IllegalArgumentException is thrown when a null property value is passed to the Hadoop Configuration, specifically during the initialization of the HttpServer. This issue arises when the web server attempts to set a configuration property that is not properly defined.",
            "StackTrace": [
                "java.lang.IllegalArgumentException: Property value must not be null",
                "at com.google.common.base.Preconditions.checkArgument(Preconditions.java:92)",
                "at org.apache.hadoop.conf.Configuration.set(Configuration.java:958)",
                "at org.apache.hadoop.conf.Configuration.set(Configuration.java:940)",
                "at org.apache.hadoop.http.HttpServer.initializeWebServer(HttpServer.java:510)",
                "at org.apache.hadoop.http.HttpServer.<init>(HttpServer.java:470)",
                "at org.apache.hadoop.http.HttpServer.<init>(HttpServer.java:458)",
                "at org.apache.hadoop.http.HttpServer.<init>(HttpServer.java:412)",
                "at org.apache.hadoop.hbase.util.InfoServer.<init>(InfoServer.java:59)",
                "at org.apache.hadoop.hbase.master.HMaster.run(HMaster.java:584)",
                "at java.lang.Thread.run(Thread.java:722)"
            ],
            "RootCause": "A null property value is being set in the Hadoop Configuration, likely due to a missing or improperly configured property in the application settings.",
            "StepsToReproduce": [
                "Attempt to start the Hadoop HMaster service.",
                "Ensure that the configuration files (e.g., hadoop-site.xml) are loaded.",
                "Check for any missing properties that are required for the HttpServer initialization."
            ],
            "ExpectedBehavior": "The Hadoop HMaster service should start without throwing an IllegalArgumentException, and the web server should initialize successfully.",
            "ObservedBehavior": "The Hadoop HMaster service fails to start, throwing an IllegalArgumentException indicating that a property value must not be null.",
            "Suggestions": "Review the Hadoop configuration files to ensure all required properties are defined and have valid values. Pay particular attention to properties related to the HttpServer and ensure none are set to null."
        }
    },
    {
        "filename": "HADOOP-12239.json",
        "creation_time": "2015-07-15T18:06:14.000+0000",
        "bug_report": {
            "Title": "IOException during log splitting in HBase",
            "Description": "An IOException occurred while attempting to split logs for a worker node in HBase, indicating issues with renaming a folder in Azure Blob Storage due to an active lease on the blob.",
            "StackTrace": [
                "java.io.IOException: failed log splitting for workernode12.xxx.b6.internal.cloudapp.net,60020,1436448556374, will retry",
                "at org.apache.hadoop.hbase.master.handler.ServerShutdownHandler.resubmit(ServerShutdownHandler.java:343)",
                "at org.apache.hadoop.hbase.master.handler.ServerShutdownHandler.process(ServerShutdownHandler.java:211)",
                "at org.apache.hadoop.hbase.executor.EventHandler.run(EventHandler.java:128)",
                "at java.util.concurrent.ThreadPoolExecutor.runWorker(ThreadPoolExecutor.java:1145)",
                "at java.util.concurrent.ThreadPoolExecutor$Worker.run(ThreadPoolExecutor.java:615)",
                "at java.lang.Thread.run(Thread.java:745)",
                "Caused by: java.io.IOException: Unable to write RenamePending file for folder rename from hbase/WALs/workernode12.xxx.b6.internal.cloudapp.net,60020,1436448566374 to hbase/WALs/workernode12.xxx.b6.internal.cloudapp.net,60020,1436448566374-splitting",
                "at org.apache.hadoop.fs.azure.NativeAzureFileSystem$FolderRenamePending.writeFile(NativeAzureFileSystem.java:258)",
                "at org.apache.hadoop.fs.azure.NativeAzureFileSystem.prepareAtomicFolderRename(NativeAzureFileSystem.java:2110)",
                "at org.apache.hadoop.fs.azure.NativeAzureFileSystem.rename(NativeAzureFileSystem.java:1998)",
                "at org.apache.hadoop.hbase.master.MasterFileSystem.getLogDirs(MasterFileSystem.java:325)",
                "at org.apache.hadoop.hbase.master.MasterFileSystem.splitLog(MasterFileSystem.java:412)",
                "at org.apache.hadoop.hbase.master.MasterFileSystem.splitLog(MasterFileSystem.java:390)",
                "at org.apache.hadoop.hbase.master.MasterFileSystem.splitLog(MasterFileSystem.java:288)",
                "at org.apache.hadoop.hbase.master.handler.ServerShutdownHandler.process(ServerShutdownHandler.java:204)",
                "... 4 more",
                "Caused by: org.apache.hadoop.fs.azure.AzureException: com.microsoft.azure.storage.StorageException: There is currently a lease on the blob and no lease ID was specified in the request.",
                "at org.apache.hadoop.fs.azure.AzureNativeFileSystemStore.updateFolderLastModifiedTime(AzureNativeFileSystemStore.java:2598)",
                "at org.apache.hadoop.fs.azure.AzureNativeFileSystemStore.updateFolderLastModifiedTime(AzureNativeFileSystemStore.java:2609)",
                "at org.apache.hadoop.fs.azure.NativeAzureFileSystem.create(NativeAzureFileSystem.java:1366)",
                "at org.apache.hadoop.fs.azure.NativeAzureFileSystem.create(NativeAzureFileSystem.java:1195)",
                "at org.apache.hadoop.fs.FileSystem.create(FileSystem.java:908)",
                "at org.apache.hadoop.fs.FileSystem.create(FileSystem.java:889)",
                "at org.apache.hadoop.fs.FileSystem.create(FileSystem.java:786)",
                "at org.apache.hadoop.fs.FileSystem.create(FileSystem.java:775)",
                "at org.apache.hadoop.fs.azure.NativeAzureFileSystem$FolderRenamePending.writeFile(NativeAzureFileSystem.java:255)",
                "... 11 more",
                "Caused by: com.microsoft.azure.storage.StorageException: There is currently a lease on the blob and no lease ID was specified in the request.",
                "at com.microsoft.azure.storage.StorageException.translateException(StorageException.java:89)",
                "at com.microsoft.azure.storage.core.StorageRequest.materializeException(StorageRequest.java:307)",
                "at com.microsoft.azure.storage.core.ExecutionEngine.executeWithRetry(ExecutionEngine.java:182)",
                "at com.microsoft.azure.storage.blob.CloudBlob.uploadProperties(CloudBlob.java:2892)",
                "at org.apache.hadoop.fs.azure.StorageInterfaceImpl$CloudBlobWrapperImpl.uploadProperties(StorageInterfaceImpl.java:372)",
                "at org.apache.hadoop.fs.azure.AzureNativeFileSystemStore.updateFolderLastModifiedTime(AzureNativeFileSystemStore.java:2593)"
            ],
            "RootCause": "The root cause of the issue is an active lease on the blob in Azure Blob Storage, which prevents the renaming operation required for log splitting.",
            "StepsToReproduce": [
                "Attempt to split logs for a worker node in HBase while there is an active lease on the corresponding blob in Azure.",
                "Monitor the logs for IOException related to folder renaming."
            ],
            "ExpectedBehavior": "The log splitting operation should complete successfully without any IOException, allowing the HBase master to manage logs appropriately.",
            "ObservedBehavior": "An IOException is thrown indicating a failure in log splitting due to an inability to rename a folder because of an active lease on the blob.",
            "Suggestions": "Check for any active leases on the blob in Azure Blob Storage. If necessary, release the lease or wait for it to expire before attempting the log splitting operation again. Additionally, consider implementing lease management in the application to handle such scenarios more gracefully."
        }
    },
    {
        "filename": "HADOOP-11878.json",
        "creation_time": "2015-04-27T08:06:22.000+0000",
        "bug_report": {
            "Title": "NullPointerException in FileContext.fixRelativePart",
            "Description": "A NullPointerException is thrown in the fixRelativePart method of the FileContext class when attempting to delete a file. This issue arises during the execution of the deleteAsUser method in the DefaultContainerExecutor class.",
            "StackTrace": [
                "java.lang.NullPointerException",
                "at org.apache.hadoop.fs.FileContext.fixRelativePart(FileContext.java:274)",
                "at org.apache.hadoop.fs.FileContext.delete(FileContext.java:761)",
                "at org.apache.hadoop.yarn.server.nodemanager.DefaultContainerExecutor.deleteAsUser(DefaultContainerExecutor.java:457)",
                "at org.apache.hadoop.yarn.server.nodemanager.DeletionService$FileDeletionTask.run(DeletionService.java:293)",
                "at java.util.concurrent.Executors$RunnableAdapter.call(Executors.java:511)",
                "at java.util.concurrent.FutureTask.run(FutureTask.java:266)",
                "at java.util.concurrent.ScheduledThreadPoolExecutor$ScheduledFutureTask.access$201(ScheduledThreadPoolExecutor.java:180)",
                "at java.util.concurrent.ScheduledThreadPoolExecutor$ScheduledFutureTask.run(ScheduledThreadPoolExecutor.java:293)",
                "at java.util.concurrent.ThreadPoolExecutor.runWorker(ThreadPoolExecutor.java:1142)",
                "at java.util.concurrent.ThreadPoolExecutor$Worker.run(ThreadPoolExecutor.java:617)",
                "at java.lang.Thread.run(Thread.java:745)"
            ],
            "RootCause": "The specific cause of the NullPointerException cannot be determined due to the unavailability of the source code for the relevant methods in the stack trace. However, it is likely related to a null reference being passed to the fixRelativePart method.",
            "StepsToReproduce": [
                "Attempt to delete a file using the FileContext.delete method.",
                "Ensure that the file context is properly initialized.",
                "Monitor the execution to capture the stack trace when the exception occurs."
            ],
            "ExpectedBehavior": "The file should be deleted without any exceptions being thrown.",
            "ObservedBehavior": "A NullPointerException is thrown, preventing the file from being deleted.",
            "Suggestions": "Investigate the initialization of the FileContext object and ensure that all necessary parameters are correctly set before invoking the delete method. Additionally, review the fixRelativePart method to identify potential null references."
        }
    },
    {
        "filename": "HADOOP-14949.json",
        "creation_time": "2017-10-13T23:44:09.000+0000",
        "bug_report": {
            "Title": "AssertionError in TestKMS: Unexpected Reencryption of Encrypted Key",
            "Description": "A test case in the TestKMS class failed due to an AssertionError indicating that the system should not allow the re-encryption of an already encrypted key. This suggests a potential flaw in the key management logic or the test setup itself.",
            "StackTrace": [
                "java.lang.AssertionError: Should not have been able to reencryptEncryptedKey",
                "at org.junit.Assert.fail(Assert.java:88)",
                "at org.apache.hadoop.crypto.key.kms.server.TestKMS$11$15.run(TestKMS.java:1616)",
                "at org.apache.hadoop.crypto.key.kms.server.TestKMS$11$15.run(TestKMS.java:1608)",
                "at java.security.AccessController.doPrivileged(Native Method)",
                "at javax.security.auth.Subject.doAs(Subject.java:415)",
                "at org.apache.hadoop.security.UserGroupInformation.doAs(UserGroupInformation.java:1917)",
                "at org.apache.hadoop.crypto.key.kms.server.TestKMS.doAs(TestKMS.java:313)",
                "at org.apache.hadoop.crypto.key.kms.server.TestKMS.access$100(TestKMS.java:97)"
            ],
            "RootCause": "The test case in TestKMS is failing due to an unexpected condition where an encrypted key is being allowed to be re-encrypted, which contradicts the expected behavior defined in the test.",
            "StepsToReproduce": [
                "Run the test suite for the TestKMS class.",
                "Ensure that the environment is set up to test key management functionalities.",
                "Observe the failure in the specific test case that checks for re-encryption of an encrypted key."
            ],
            "ExpectedBehavior": "The system should prevent the re-encryption of an already encrypted key, and the test should pass without throwing an AssertionError.",
            "ObservedBehavior": "The test fails with an AssertionError, indicating that the system incorrectly allows the re-encryption of an encrypted key.",
            "Suggestions": "Review the implementation of the key management logic in the KMS to ensure that it correctly enforces the rules regarding key re-encryption. Additionally, verify the test setup to ensure that the initial state of the key is correctly established before the test runs."
        }
    },
    {
        "filename": "HADOOP-10540.json",
        "creation_time": "2014-04-11T05:14:07.000+0000",
        "bug_report": {
            "Title": "IOException due to Incorrect Command Line Arguments in HardLink Creation",
            "Description": "An IOException is thrown when attempting to create hard links due to incorrect command line arguments passed to the createHardLinkMult method in the HardLink class. This issue occurs during the DataNode's storage initialization process.",
            "StackTrace": [
                "java.io.IOException: Usage: hardlink create [LINKNAME] [FILENAME] |Incorrect command line arguments.",
                "at org.apache.hadoop.fs.HardLink.createHardLinkMult(HardLink.java:479)",
                "at org.apache.hadoop.fs.HardLink.createHardLinkMult(HardLink.java:416)",
                "at org.apache.hadoop.hdfs.server.datanode.DataStorage.linkBlocks(DataStorage.java:816)",
                "at org.apache.hadoop.hdfs.server.datanode.DataStorage.linkAllBlocks(DataStorage.java:759)",
                "at org.apache.hadoop.hdfs.server.datanode.DataStorage.doUpgrade(DataStorage.java:566)",
                "at org.apache.hadoop.hdfs.server.datanode.DataStorage.doTransition(DataStorage.java:486)",
                "at org.apache.hadoop.hdfs.server.datanode.DataStorage.recoverTransitionRead(DataStorage.java:225)",
                "at org.apache.hadoop.hdfs.server.datanode.DataStorage.recoverTransitionRead(DataStorage.java:249)",
                "at org.apache.hadoop.hdfs.server.datanode.DataNode.initStorage(DataNode.java:929)",
                "at org.apache.hadoop.hdfs.server.datanode.DataNode.initBlockPool(DataNode.java:900)",
                "at org.apache.hadoop.hdfs.server.datanode.BPOfferService.verifyAndSetNamespaceInfo(BPOfferService.java:274)",
                "at org.apache.hadoop.hdfs.server.datanode.BPServiceActor.connectToNNAndHandshake(BPServiceActor.java:220)",
                "at org.apache.hadoop.hdfs.server.datanode.BPServiceActor.run(BPServiceActor.java:815)",
                "at java.lang.Thread.run(Thread.java:722)"
            ],
            "RootCause": "The root cause of the IOException is the incorrect command line arguments provided to the createHardLinkMult method, which expects specific parameters for creating hard links.",
            "StepsToReproduce": [
                "Attempt to create a hard link using the command line interface with incorrect arguments.",
                "Monitor the logs for IOException related to hard link creation."
            ],
            "ExpectedBehavior": "The hard link should be created successfully without any exceptions if the correct command line arguments are provided.",
            "ObservedBehavior": "An IOException is thrown indicating incorrect command line arguments, preventing the creation of the hard link.",
            "Suggestions": "Verify the command line arguments being passed to the hard link creation command. Ensure that the arguments conform to the expected format: 'hardlink create [LINKNAME] [FILENAME]'. Additionally, consider adding input validation to provide clearer error messages for incorrect usage."
        }
    },
    {
        "filename": "HADOOP-7629.json",
        "creation_time": "2011-09-09T17:45:14.000+0000",
        "bug_report": {
            "Title": "NoSuchMethodException for FsPermission$2 Constructor in Hadoop",
            "Description": "A RuntimeException is thrown due to a NoSuchMethodException when attempting to instantiate the inner class FsPermission$2 using reflection. This occurs within the Hadoop framework during the deserialization process of an ObjectWritable.",
            "StackTrace": [
                "java.lang.RuntimeException: java.lang.NoSuchMethodException: org.apache.hadoop.fs.permission.FsPermission$2.<init>()",
                "at org.apache.hadoop.util.ReflectionUtils.newInstance(ReflectionUtils.java:115)",
                "at org.apache.hadoop.io.WritableFactories.newInstance(WritableFactories.java:53)",
                "at org.apache.hadoop.io.ObjectWritable.readObject(ObjectWritable.java:236)",
                "at org.apache.hadoop.ipc.RPC$Invocation.readFields(RPC.java:104)",
                "at org.apache.hadoop.ipc.Server$Connection.processData(Server.java:1337)",
                "at org.apache.hadoop.ipc.Server$Connection.processOneRpc(Server.java:1315)",
                "at org.apache.hadoop.ipc.Server$Connection.readAndProcess(Server.java:1215)",
                "at org.apache.hadoop.ipc.Server$Listener.doRead(Server.java:566)",
                "at org.apache.hadoop.ipc.Server$Listener$Reader.run(Server.java:363)",
                "Caused by: java.lang.NoSuchMethodException: org.apache.hadoop.fs.permission.FsPermission$2.<init>()",
                "at java.lang.Class.getConstructor0(Class.java:2706)",
                "at java.lang.Class.getDeclaredConstructor(Class.java:1985)",
                "at org.apache.hadoop.util.ReflectionUtils.newInstance(ReflectionUtils.java:109)"
            ],
            "RootCause": "The constructor for the inner class FsPermission$2 is not accessible, likely due to it not being public or not having the required visibility for reflection.",
            "StepsToReproduce": [
                "Attempt to serialize and deserialize an instance of org.apache.hadoop.fs.permission.FsPermission$2.",
                "Ensure that the deserialization process is invoked through the Hadoop IPC mechanism."
            ],
            "ExpectedBehavior": "The inner class FsPermission$2 should be instantiated successfully without throwing a NoSuchMethodException.",
            "ObservedBehavior": "A RuntimeException is thrown indicating that the constructor for FsPermission$2 cannot be found.",
            "Suggestions": "Check the visibility of the constructor for FsPermission$2. If it is not public, consider modifying it to be public or providing a public factory method for instantiation. Additionally, review the serialization and deserialization logic to ensure compatibility with the expected class structure."
        }
    },
    {
        "filename": "HADOOP-15060.json",
        "creation_time": "2017-11-22T00:18:55.000+0000",
        "bug_report": {
            "Title": "AssertionError in testFiniteGroupResolutionTime due to missing user",
            "Description": "The test case 'testFiniteGroupResolutionTime' in the 'TestShellBasedUnixGroupsMapping' class is failing due to an AssertionError. The test expected a log message indicating a command timeout, but instead, it received a warning about a non-existing user.",
            "StackTrace": [
                "java.lang.AssertionError: Expected the logs to carry a message about command timeout but was: 2017-11-22 00:10:57,523 WARN  security.ShellBasedUnixGroupsMapping (ShellBasedUnixGroupsMapping.java:getUnixGroups(181)) - unable to return groups for user foobarnonexistinguser",
                "PartialGroupNameException The user name 'foobarnonexistinguser' is not found.",
                "at org.apache.hadoop.security.ShellBasedUnixGroupsMapping.resolvePartialGroupNames(ShellBasedUnixGroupsMapping.java:275)",
                "at org.apache.hadoop.security.ShellBasedUnixGroupsMapping.getUnixGroups(ShellBasedUnixGroupsMapping.java:178)",
                "at org.apache.hadoop.security.ShellBasedUnixGroupsMapping.getGroups(ShellBasedUnixGroupsMapping.java:97)",
                "at org.apache.hadoop.security.TestShellBasedUnixGroupsMapping.testFiniteGroupResolutionTime(TestShellBasedUnixGroupsMapping.java:278)"
            ],
            "RootCause": "The test case did not simulate the expected conditions for a command timeout, leading to a warning about a non-existing user instead of the expected log message.",
            "StepsToReproduce": [
                "Run the test case 'testFiniteGroupResolutionTime' in the 'TestShellBasedUnixGroupsMapping' class.",
                "Ensure that the user 'foobarnonexistinguser' is not present in the system.",
                "Observe the log output during the test execution."
            ],
            "ExpectedBehavior": "The test should log a message indicating a command timeout.",
            "ObservedBehavior": "The test logs a warning about the user 'foobarnonexistinguser' not being found instead of the expected command timeout message.",
            "Suggestions": "Review the setup of the test case 'testFiniteGroupResolutionTime' to ensure it correctly simulates the conditions for a command timeout. Consider mocking the user lookup or adjusting the test to use a valid user."
        }
    },
    {
        "filename": "HADOOP-10937.json",
        "creation_time": "2014-08-04T21:22:55.000+0000",
        "bug_report": {
            "Title": "NullPointerException in KMSClientProvider during Key Decryption",
            "Description": "A NullPointerException is thrown in the KMSClientProvider class while attempting to decrypt an encrypted key. This issue arises during file system operations in the Hadoop framework, specifically when creating a wrapped output stream.",
            "StackTrace": [
                "java.lang.NullPointerException",
                "at org.apache.hadoop.crypto.key.kms.KMSClientProvider.decryptEncryptedKey(KMSClientProvider.java:652)",
                "at org.apache.hadoop.crypto.key.KeyProviderCryptoExtension.decryptEncryptedKey(KeyProviderCryptoExtension.java:342)",
                "at org.apache.hadoop.hdfs.DFSClient.decryptEncryptedDataEncryptionKey(DFSClient.java:1319)",
                "at org.apache.hadoop.hdfs.DFSClient.createWrappedOutputStream(DFSClient.java:1364)",
                "at org.apache.hadoop.hdfs.DFSClient.createWrappedOutputStream(DFSClient.java:1352)",
                "at org.apache.hadoop.hdfs.DistributedFileSystem$6.doCall(DistributedFileSystem.java:391)",
                "at org.apache.hadoop.hdfs.DistributedFileSystem$6.doCall(DistributedFileSystem.java:384)",
                "at org.apache.hadoop.fs.FileSystemLinkResolver.resolve(FileSystemLinkResolver.java:81)",
                "at org.apache.hadoop.hdfs.DistributedFileSystem.create(DistributedFileSystem.java:384)",
                "at org.apache.hadoop.hdfs.DistributedFileSystem.create(DistributedFileSystem.java:328)",
                "at org.apache.hadoop.fs.FileSystem.create(FileSystem.java:906)",
                "at org.apache.hadoop.fs.FileSystem.create(FileSystem.java:887)"
            ],
            "RootCause": "The NullPointerException is likely caused by uninitialized objects or variables related to encryption keys being passed to the decryptEncryptedKey method.",
            "StepsToReproduce": [
                "Attempt to create a new file in a Hadoop Distributed File System (HDFS) with encryption enabled.",
                "Ensure that the encryption key provider is configured but may not have valid keys initialized.",
                "Observe the logs for the NullPointerException during the file creation process."
            ],
            "ExpectedBehavior": "The system should successfully create a new file in HDFS with the appropriate encryption applied, without throwing any exceptions.",
            "ObservedBehavior": "A NullPointerException is thrown, indicating that an attempt was made to access a null reference during the decryption of the encryption key.",
            "Suggestions": "Check the initialization of encryption keys in the KMSClientProvider. Ensure that all necessary keys are properly configured and available before attempting to create files with encryption. Additionally, add null checks in the decryptEncryptedKey method to handle cases where the key may not be initialized."
        }
    },
    {
        "filename": "HADOOP-9103.json",
        "creation_time": "2012-04-20T01:07:25.000+0000",
        "bug_report": {
            "Title": "IOException: Found lease for non-existent file in Hadoop",
            "Description": "An IOException is thrown when the Hadoop system attempts to load files under construction, but encounters a lease for a file that does not exist. This issue arises during the checkpointing process in the SecondaryNameNode.",
            "StackTrace": [
                "java.io.IOException: Found lease for non-existent file /user/boss/pgv/fission/task16/split/_temporary/_attempt_201203271849_0016_r_000174_0/????@???????????????",
                "at org.apache.hadoop.hdfs.server.namenode.FSImage.loadFilesUnderConstruction(FSImage.java:1211)",
                "at org.apache.hadoop.hdfs.server.namenode.FSImage.loadFSImage(FSImage.java:959)",
                "at org.apache.hadoop.hdfs.server.namenode.SecondaryNameNode$CheckpointStorage.doMerge(SecondaryNameNode.java:589)",
                "at org.apache.hadoop.hdfs.server.namenode.SecondaryNameNode$CheckpointStorage.access$000(SecondaryNameNode.java:473)",
                "at org.apache.hadoop.hdfs.server.namenode.SecondaryNameNode.doMerge(SecondaryNameNode.java:350)",
                "at org.apache.hadoop.hdfs.server.namenode.SecondaryNameNode.doCheckpoint(SecondaryNameNode.java:314)",
                "at org.apache.hadoop.hdfs.server.namenode.SecondaryNameNode.run(SecondaryNameNode.java:225)",
                "at java.lang.Thread.run(Thread.java:619)"
            ],
            "RootCause": "The system is attempting to access a file that should exist but does not, likely due to a failure in file creation or cleanup processes.",
            "StepsToReproduce": [
                "Initiate a Hadoop job that creates temporary files.",
                "Allow the job to run until it reaches the checkpointing phase.",
                "Monitor the logs for any IOException related to non-existent files."
            ],
            "ExpectedBehavior": "The Hadoop system should successfully load files under construction and complete the checkpointing process without errors.",
            "ObservedBehavior": "An IOException is thrown indicating a lease for a non-existent file, causing the checkpointing process to fail.",
            "Suggestions": "Investigate the file creation and cleanup processes in the Hadoop job. Ensure that temporary files are being created correctly and that any cleanup operations are not prematurely deleting files that are still in use. Review the Hadoop documentation for best practices regarding file management and lease handling."
        }
    },
    {
        "filename": "HADOOP-11151.json",
        "creation_time": "2014-09-29T08:18:04.000+0000",
        "bug_report": {
            "Title": "AuthenticationException: Anonymous requests are disallowed",
            "Description": "The application is rejecting requests due to missing authentication credentials, resulting in an AuthenticationException. This issue arises when users attempt to access secured resources without proper authentication.",
            "StackTrace": [
                "org.apache.hadoop.security.authentication.client.AuthenticationException: Anonymous requests are disallowed",
                "at org.apache.hadoop.security.authentication.server.PseudoAuthenticationHandler.authenticate(PseudoAuthenticationHandler.java:184)",
                "at org.apache.hadoop.security.token.delegation.web.DelegationTokenAuthenticationHandler.authenticate(DelegationTokenAuthenticationHandler.java:331)",
                "at org.apache.hadoop.security.authentication.server.AuthenticationFilter.doFilter(AuthenticationFilter.java:507)",
                "at org.apache.hadoop.crypto.key.kms.server.KMSAuthenticationFilter.doFilter(KMSAuthenticationFilter.java:129)",
                "at org.apache.catalina.core.ApplicationFilterChain.internalDoFilter(ApplicationFilterChain.java:235)",
                "at org.apache.catalina.core.ApplicationFilterChain.doFilter(ApplicationFilterChain.java:206)",
                "at org.apache.catalina.core.StandardWrapperValve.invoke(StandardWrapperValve.java:233)",
                "at org.apache.catalina.core.StandardContextValve.invoke(StandardContextValve.java:191)",
                "at org.apache.catalina.core.StandardHostValve.invoke(StandardHostValve.java:127)",
                "at org.apache.catalina.valves.ErrorReportValve.invoke(ErrorReportValve.java:103)",
                "at org.apache.catalina.core.StandardEngineValve.invoke(StandardEngineValve.java:109)",
                "at org.apache.catalina.connector.CoyoteAdapter.service(CoyoteAdapter.java:293)",
                "at org.apache.coyote.http11.Http11Processor.process(Http11Processor.java:861)",
                "at org.apache.coyote.http11.Http11Protocol$Http11ConnectionHandler.process(Http11Protocol.java:606)",
                "at org.apache.tomcat.util.net.JIoEndpoint$Worker.run(JIoEndpoint.java:489)",
                "at java.lang.Thread.run(Thread.java:745)"
            ],
            "RootCause": "The application is configured to disallow anonymous requests, leading to the rejection of requests without authentication credentials.",
            "StepsToReproduce": [
                "Attempt to access a secured resource without providing authentication credentials.",
                "Observe the resulting AuthenticationException in the logs."
            ],
            "ExpectedBehavior": "Requests to secured resources should be processed successfully when valid authentication credentials are provided.",
            "ObservedBehavior": "Requests without authentication credentials are rejected, resulting in an AuthenticationException.",
            "Suggestions": "Ensure that all requests to secured resources include valid authentication credentials. Review the authentication configuration to confirm that anonymous access is appropriately managed based on application requirements."
        }
    },
    {
        "filename": "HADOOP-8031.json",
        "creation_time": "2012-02-07T20:22:24.000+0000",
        "bug_report": {
            "Title": "Missing core-site.xml Configuration File",
            "Description": "The application fails to start the Hadoop NameNode component due to a missing core-site.xml configuration file, resulting in a PluginContainerException.",
            "StackTrace": [
                "org.rhq.core.clientapi.agent.PluginContainerException: Failed to start component for resource Resource[id=16290, type=NameNode, key=NameNode:/usr/lib/hadoop-0.20, name=NameNode, parent=vg61l01ad-hadoop002.apple.com].",
                "Caused by: java.lang.RuntimeException: core-site.xml not found",
                "at org.apache.hadoop.conf.Configuration.loadResource(Configuration.java:1308)",
                "at org.apache.hadoop.conf.Configuration.loadResources(Configuration.java:1228)",
                "at org.apache.hadoop.conf.Configuration.getProps(Configuration.java:1169)",
                "at org.apache.hadoop.conf.Configuration.set(Configuration.java:438)"
            ],
            "RootCause": "The core-site.xml configuration file is not found in the expected directory, which is essential for the Hadoop configuration.",
            "StepsToReproduce": [
                "Attempt to start the Hadoop NameNode component.",
                "Observe the error message indicating that core-site.xml is missing."
            ],
            "ExpectedBehavior": "The Hadoop NameNode component should start successfully without any configuration errors.",
            "ObservedBehavior": "The application throws a PluginContainerException due to the absence of the core-site.xml file.",
            "Suggestions": "Ensure that the core-site.xml file is present in the Hadoop configuration directory (typically /usr/lib/hadoop-0.20/conf/). Verify that the application has the necessary permissions to access this file."
        }
    },
    {
        "filename": "HADOOP-15411.json",
        "creation_time": "2018-04-24T23:18:39.000+0000",
        "bug_report": {
            "Title": "YarnRuntimeException: NMWebapps failed to start due to ConcurrentModificationException",
            "Description": "The NodeManager's web application failed to start, resulting in a YarnRuntimeException. The underlying cause is a ConcurrentModificationException occurring during the initialization of the HTTP server, indicating potential issues with concurrent access to configuration settings.",
            "StackTrace": [
                "org.apache.hadoop.yarn.exceptions.YarnRuntimeException: NMWebapps failed to start.",
                "at org.apache.hadoop.yarn.server.nodemanager.webapp.WebServer.serviceStart(WebServer.java:117)",
                "at org.apache.hadoop.service.AbstractService.start(AbstractService.java:194)",
                "at org.apache.hadoop.service.CompositeService.serviceStart(CompositeService.java:121)",
                "at org.apache.hadoop.service.AbstractService.start(AbstractService.java:194)",
                "at org.apache.hadoop.yarn.server.nodemanager.NodeManager.initAndStartNodeManager(NodeManager.java:919)",
                "at org.apache.hadoop.yarn.server.nodemanager.NodeManager.main(NodeManager.java:979)",
                "Caused by: org.apache.hadoop.yarn.webapp.WebAppException: Error starting http server",
                "at org.apache.hadoop.yarn.webapp.WebApps$Builder.build(WebApps.java:377)",
                "at org.apache.hadoop.yarn.webapp.WebApps$Builder.start(WebApps.java:424)",
                "at org.apache.hadoop.yarn.webapp.WebApps$Builder.start(WebApps.java:420)",
                "at org.apache.hadoop.yarn.server.nodemanager.webapp.WebServer.serviceStart(WebServer.java:112)",
                "... 5 more",
                "Caused by: java.io.IOException: java.util.ConcurrentModificationException",
                "at org.apache.hadoop.http.HttpServer2.<init>(HttpServer2.java:532)",
                "at org.apache.hadoop.http.HttpServer2.<init>(HttpServer2.java:117)",
                "at org.apache.hadoop.http.HttpServer2$Builder.build(HttpServer2.java:421)",
                "at org.apache.hadoop.yarn.webapp.WebApps$Builder.build(WebApps.java:333)",
                "... 8 more",
                "Caused by: java.util.ConcurrentModificationException",
                "at java.util.Hashtable$Enumerator.next(Hashtable.java:1383)",
                "at org.apache.hadoop.conf.Configuration.iterator(Configuration.java:2853)",
                "at org.apache.hadoop.security.AuthenticationFilterInitializer.getFilterConfigMap(AuthenticationFilterInitializer.java:73)",
                "at org.apache.hadoop.http.HttpServer2.getFilterProperties(HttpServer2.java:647)",
                "at org.apache.hadoop.http.HttpServer2.constructSecretProvider(HttpServer2.java:637)",
                "at org.apache.hadoop.http.HttpServer2.<init>(HttpServer2.java:525)"
            ],
            "RootCause": "The root cause of the issue is a ConcurrentModificationException occurring during the initialization of the HttpServer2, which is triggered by concurrent modifications to the configuration settings.",
            "StepsToReproduce": [
                "Start the NodeManager service in a multi-threaded environment.",
                "Ensure multiple threads attempt to modify the configuration settings simultaneously.",
                "Observe the logs for YarnRuntimeException indicating NMWebapps failed to start."
            ],
            "ExpectedBehavior": "The NodeManager should start successfully without any exceptions, and the web application should be accessible.",
            "ObservedBehavior": "The NodeManager fails to start, throwing a YarnRuntimeException due to an underlying IOException caused by a ConcurrentModificationException.",
            "Suggestions": "Review the code in the Configuration management to ensure thread safety. Consider using concurrent collections or synchronization mechanisms to prevent concurrent modifications. Additionally, implement logging to capture the state of configuration modifications to aid in debugging."
        }
    },
    {
        "filename": "HADOOP-15850.json",
        "creation_time": "2018-10-13T14:24:29.000+0000",
        "bug_report": {
            "Title": "IOException: Inconsistent Sequence File During Copy Operation",
            "Description": "An IOException is thrown during a copy operation in Hadoop, indicating an inconsistency between the current chunk file and the prior entry in the sequence file. This issue arises within the CopyCommitter class, specifically during the concatenation of file chunks.",
            "StackTrace": [
                "java.io.IOException: Inconsistent sequence file: current chunk file org.apache.hadoop.tools.CopyListingFileStatus@bb8826ee{hdfs://localhost:42796/user/hbase/test-data/160aeab5-6bca-9f87-465e-2517a0c43119/data/default/test-1539439707496/96b5a3613d52f4df1ba87a1cef20684c/f/a7599081e835440eb7bf0dd3ef4fd7a5_SeqId_205_ length = 5100 aclEntries  = null, xAttrs = null} doesnt match prior entry org.apache.hadoop.tools.CopyListingFileStatus@243d544d{hdfs://localhost:42796/user/hbase/test-data/160aeab5-6bca-9f87-465e-2517a0c43119/data/default/test-1539439707496/96b5a3613d52f4df1ba87a1cef20684c/f/394e6d39a9b94b148b9089c4fb967aad_SeqId_205_ length = 5142 aclEntries = null, xAttrs = null}",
                "at org.apache.hadoop.tools.mapred.CopyCommitter.concatFileChunks(CopyCommitter.java:276)",
                "at org.apache.hadoop.tools.mapred.CopyCommitter.commitJob(CopyCommitter.java:100)",
                "at org.apache.hadoop.mapred.LocalJobRunner$Job.run(LocalJobRunner.java:567)"
            ],
            "RootCause": "The inconsistency between the current chunk file and the prior entry suggests potential data integrity issues, possibly due to concurrent modifications or corruption during the copy process.",
            "StepsToReproduce": [
                "Initiate a copy operation using the Hadoop CopyCommitter.",
                "Ensure that the source data contains multiple sequence files.",
                "Monitor the copy process for any interruptions or concurrent modifications."
            ],
            "ExpectedBehavior": "The copy operation should successfully concatenate all sequence files without any inconsistencies, resulting in a single, coherent output file.",
            "ObservedBehavior": "An IOException is thrown, indicating that the current chunk file does not match the prior entry, leading to a failure in the copy operation.",
            "Suggestions": "Investigate the source data for any corruption or inconsistencies. Ensure that no concurrent processes are modifying the sequence files during the copy operation. Consider adding validation checks before concatenating file chunks to prevent such inconsistencies."
        }
    },
    {
        "filename": "HADOOP-11693.json",
        "creation_time": "2015-03-05T23:19:13.000+0000",
        "bug_report": {
            "Title": "Azure Storage Busy Exception Causing HBase Log Splitting Failures",
            "Description": "The application is encountering exceptions related to Azure storage being busy, which is leading to failures in log splitting and serving regions in HBase. This issue is causing cascading failures in HBase operations, impacting the overall functionality of the system.",
            "StackTrace": [
                "org.apache.hadoop.fs.azure.AzureException: com.microsoft.windowsazure.storage.StorageException: The server is busy.",
                "at org.apache.hadoop.fs.azurenative.AzureNativeFileSystemStore.rename(AzureNativeFileSystemStore.java:2446)",
                "at org.apache.hadoop.fs.azurenative.AzureNativeFileSystemStore.rename(AzureNativeFileSystemStore.java:2367)",
                "at org.apache.hadoop.fs.azurenative.NativeAzureFileSystem.rename(NativeAzureFileSystem.java:1960)",
                "at org.apache.hadoop.hbase.util.FSUtils.renameAndSetModifyTime(FSUtils.java:1719)",
                "at org.apache.hadoop.hbase.regionserver.wal.FSHLog.archiveLogFile(FSHLog.java:798)",
                "at org.apache.hadoop.hbase.regionserver.wal.FSHLog.cleanOldLogs(FSHLog.java:656)",
                "at org.apache.hadoop.hbase.regionserver.wal.FSHLog.rollWriter(FSHLog.java:593)",
                "at org.apache.hadoop.hbase.regionserver.LogRoller.run(LogRoller.java:97)",
                "at java.lang.Thread.run(Thread.java:745)",
                "Caused by: com.microsoft.windowsazure.storage.StorageException: The server is busy.",
                "at com.microsoft.windowsazure.storage.StorageException.translateException(StorageException.java:163)",
                "at com.microsoft.windowsazure.storage.core.StorageRequest.materializeException(StorageRequest.java:306)",
                "at com.microsoft.windowsazure.storage.core.ExecutionEngine.executeWithRetry(ExecutionEngine.java:229)",
                "at com.microsoft.windowsazure.storage.blob.CloudBlob.startCopyFromBlob(CloudBlob.java:762)",
                "at org.apache.hadoop.fs.azurenative.StorageInterfaceImpl$CloudBlobWrapperImpl.startCopyFromBlob(StorageInterfaceImpl.java:350)",
                "at org.apache.hadoop.fs.azurenative.AzureNativeFileSystemStore.rename(AzureNativeFileSystemStore.java:2439)",
                "... 8 more",
                "java.io.IOException: failed log splitting for workernode13.hbaseproddb4001.f5.internal.cloudapp.net,60020,1424845307901, will retry",
                "at org.apache.hadoop.hbase.master.handler.MetaServerShutdownHandler.process(MetaServerShutdownHandler.java:71)",
                "at org.apache.hadoop.hbase.executor.EventHandler.run(EventHandler.java:128)",
                "at java.util.concurrent.ThreadPoolExecutor.runWorker(ThreadPoolExecutor.java:1145)",
                "at java.util.concurrent.ThreadPoolExecutor$Worker.run(ThreadPoolExecutor.java:615)",
                "at java.lang.Thread.run(Thread.java:745)",
                "Caused by: org.apache.hadoop.fs.azure.AzureException: com.microsoft.windowsazure.storage.StorageException: The server is busy.",
                "at org.apache.hadoop.fs.azurenative.AzureNativeFileSystemStore.rename(AzureNativeFileSystemStore.java:2446)",
                "at org.apache.hadoop.fs.azurenative.NativeAzureFileSystem$FolderRenamePending.execute(NativeAzureFileSystem.java:393)",
                "at org.apache.hadoop.fs.azurenative.NativeAzureFileSystem.rename(NativeAzureFileSystem.java:1973)",
                "at org.apache.hadoop.hbase.master.MasterFileSystem.getLogDirs(MasterFileSystem.java:319)",
                "at org.apache.hadoop.hbase.master.MasterFileSystem.splitLog(MasterFileSystem.java:406)",
                "at org.apache.hadoop.hbase.master.MasterFileSystem.splitMetaLog(MasterFileSystem.java:302)",
                "at org.apache.hadoop.hbase.master.MasterFileSystem.splitMetaLog(MasterFileSystem.java:293)",
                "at org.apache.hadoop.hbase.master.handler.MetaServerShutdownHandler.process(MetaServerShutdownHandler.java:64)",
                "... 4 more",
                "Caused by: com.microsoft.windowsazure.storage.StorageException: The server is busy.",
                "at com.microsoft.windowsazure.storage.StorageException.translateException(StorageException.java:163)",
                "at com.microsoft.windowsazure.storage.core.StorageRequest.materializeException(StorageRequest.java:306)",
                "at com.microsoft.windowsazure.storage.core.ExecutionEngine.executeWithRetry(ExecutionEngine.java:229)",
                "at com.microsoft.windowsazure.storage.blob.CloudBlob.startCopyFromBlob(CloudBlob.java:762)",
                "at org.apache.hadoop.fs.azurenative.StorageInterfaceImpl$CloudBlobWrapperImpl.startCopyFromBlob(StorageInterfaceImpl.java:350)",
                "at org.apache.hadoop.fs.azurenative.AzureNativeFileSystemStore.rename(AzureNativeFileSystemStore.java:2439)",
                "... 11 more",
                "org.apache.hadoop.hbase.NotServingRegionException: org.apache.hadoop.hbase.NotServingRegionException: Region hbase:meta,,1 is not online on workernode13.hbaseproddb4001.f5.internal.cloudapp.net,60020,1425235081338",
                "at org.apache.hadoop.hbase.regionserver.HRegionServer.getRegionByEncodedName(HRegionServer.java:2676)",
                "at org.apache.hadoop.hbase.regionserver.HRegionServer.getRegion(HRegionServer.java:4095)",
                "at org.apache.hadoop.hbase.regionserver.HRegionServer.scan(HRegionServer.java:3076)",
                "at org.apache.hadoop.hbase.protobuf.generated.ClientProtos$ClientService$2.callBlockingMethod(ClientProtos.java:28861)",
                "at org.apache.hadoop.hbase.ipc.RpcServer.call(RpcServer.java:2008)",
                "at org.apache.hadoop.hbase.ipc.CallRunner.run(CallRunner.java:92)",
                "at org.apache.hadoop.hbase.ipc.SimpleRpcScheduler.consumerLoop(SimpleRpcScheduler.java:160)",
                "at org.apache.hadoop.hbase.ipc.SimpleRpcScheduler.access$000(SimpleRpcScheduler.java:38)",
                "at org.apache.hadoop.hbase.ipc.SimpleRpcScheduler$1.run(SimpleRpcScheduler.java:110)",
                "at java.lang.Thread.run(Thread.java:745)"
            ],
            "RootCause": "The Azure storage service is busy, leading to failures in log splitting and region serving in HBase.",
            "StepsToReproduce": [
                "Attempt to perform log splitting in HBase while the Azure storage service is under heavy load.",
                "Monitor the Azure storage service for busy states.",
                "Check HBase logs for exceptions related to Azure storage access."
            ],
            "ExpectedBehavior": "HBase should successfully split logs and serve regions without encountering Azure storage exceptions.",
            "ObservedBehavior": "HBase fails to split logs and serve regions due to Azure storage being busy, resulting in cascading failures.",
            "Suggestions": "Consider implementing exponential backoff for retries when accessing Azure storage. Monitor Azure storage service performance and scale resources if necessary to handle load."
        }
    },
    {
        "filename": "HADOOP-12441.json",
        "creation_time": "2015-09-25T23:26:43.000+0000",
        "bug_report": {
            "Title": "Invalid Process ID Error in YARN Container Management",
            "Description": "An error occurs when attempting to signal a container in YARN, resulting in an ExitCodeException due to a garbage process ID being passed to the kill command.",
            "StackTrace": [
                "ExitCodeException exitCode=1: ERROR: garbage process ID '--'.",
                "at org.apache.hadoop.util.Shell.runCommand(Shell.java:550)",
                "at org.apache.hadoop.util.Shell.run(Shell.java:461)",
                "at org.apache.hadoop.util.Shell$ShellCommandExecutor.execute(Shell.java:727)",
                "at org.apache.hadoop.yarn.server.nodemanager.DefaultContainerExecutor.containerIsAlive(DefaultContainerExecutor.java:432)",
                "at org.apache.hadoop.yarn.server.nodemanager.DefaultContainerExecutor.signalContainer(DefaultContainerExecutor.java:401)",
                "at org.apache.hadoop.yarn.server.nodemanager.containermanager.launcher.ContainerLaunch.cleanupContainer(ContainerLaunch.java:419)",
                "at org.apache.hadoop.yarn.server.nodemanager.containermanager.launcher.ContainersLauncher.handle(ContainersLauncher.java:139)",
                "at org.apache.hadoop.yarn.server.nodemanager.containermanager.launcher.ContainersLauncher.handle(ContainersLauncher.java:55)",
                "at org.apache.hadoop.yarn.event.AsyncDispatcher.dispatch(AsyncDispatcher.java:175)",
                "at org.apache.hadoop.yarn.event.AsyncDispatcher$1.run(AsyncDispatcher.java:108)",
                "at java.lang.Thread.run(Thread.java:745)"
            ],
            "RootCause": "The error is caused by an invalid or malformed process ID being passed to the kill command, likely due to a bug in the code or the state of the container managed by YARN.",
            "StepsToReproduce": [
                "Start a YARN container that is expected to run a process.",
                "Trigger a cleanup or shutdown of the container.",
                "Observe the logs for any errors related to process signaling."
            ],
            "ExpectedBehavior": "The YARN container should be signaled correctly, allowing for a graceful shutdown without errors.",
            "ObservedBehavior": "An ExitCodeException is thrown indicating a garbage process ID, preventing the container from being signaled properly.",
            "Suggestions": "Investigate the source of the process ID being passed to the kill command. Ensure that valid process IDs are being used and add error handling to manage cases where an invalid ID is encountered. Review the state management of containers in YARN to prevent such issues."
        }
    },
    {
        "filename": "HADOOP-11685.json",
        "creation_time": "2015-03-06T22:00:14.000+0000",
        "bug_report": {
            "Title": "IOException during HBase Log Splitting due to Azure Blob Lease",
            "Description": "An IOException is thrown during the log splitting process in HBase, caused by an AzureException indicating that there is a lease on the blob and no lease ID was specified in the request. This issue occurs in the HLogSplitter class while attempting to write log entries to Azure Blob Storage.",
            "StackTrace": [
                "java.io.IOException: org.apache.hadoop.fs.azure.AzureException: java.io.IOException",
                "at org.apache.hadoop.hbase.regionserver.wal.HLogSplitter.checkForErrors(HLogSplitter.java:633)",
                "at org.apache.hadoop.hbase.regionserver.wal.HLogSplitter.access$000(HLogSplitter.java:121)",
                "at org.apache.hadoop.hbase.regionserver.wal.HLogSplitter$OutputSink.finishWriting(HLogSplitter.java:964)",
                "at org.apache.hadoop.hbase.regionserver.wal.HLogSplitter$LogRecoveredEditsOutputSink.finishWritingAndClose(HLogSplitter.java:1019)",
                "at org.apache.hadoop.hbase.regionserver.wal.HLogSplitter.splitLogFile(HLogSplitter.java:359)",
                "at org.apache.hadoop.hbase.regionserver.wal.HLogSplitter.splitLogFile(HLogSplitter.java:223)",
                "at org.apache.hadoop.hbase.regionserver.SplitLogWorker$1.exec(SplitLogWorker.java:142)",
                "at org.apache.hadoop.hbase.regionserver.handler.HLogSplitterHandler.process(HLogSplitterHandler.java:79)",
                "at org.apache.hadoop.hbase.executor.EventHandler.run(EventHandler.java:128)",
                "at java.util.concurrent.ThreadPoolExecutor.runWorker(ThreadPoolExecutor.java:1145)",
                "at java.util.concurrent.ThreadPoolExecutor$Worker.run(ThreadPoolExecutor.java:615)",
                "at java.lang.Thread.run(Thread.java:745)",
                "Caused by: org.apache.hadoop.fs.azure.AzureException: java.io.IOException",
                "at org.apache.hadoop.fs.azurenative.AzureNativeFileSystemStore.storeEmptyFolder(AzureNativeFileSystemStore.java:1477)",
                "at org.apache.hadoop.fs.azurenative.NativeAzureFileSystem.mkdirs(NativeAzureFileSystem.java:1862)",
                "at org.apache.hadoop.fs.azurenative.NativeAzureFileSystem.mkdirs(NativeAzureFileSystem.java:1812)",
                "at org.apache.hadoop.fs.FileSystem.mkdirs(FileSystem.java:1815)",
                "at org.apache.hadoop.hbase.regionserver.wal.HLogSplitter.getRegionSplitEditsPath(HLogSplitter.java:502)",
                "at org.apache.hadoop.hbase.regionserver.wal.HLogSplitter$LogRecoveredEditsOutputSink.createWAP(HLogSplitter.java:1211)",
                "at org.apache.hadoop.hbase.regionserver.wal.HLogSplitter$LogRecoveredEditsOutputSink.getWriterAndPath(HLogSplitter.java:1200)",
                "at org.apache.hadoop.hbase.regionserver.wal.HLogSplitter$LogRecoveredEditsOutputSink.append(HLogSplitter.java:1243)",
                "at org.apache.hadoop.hbase.regionserver.wal.HLogSplitter$WriterThread.writeBuffer(HLogSplitter.java:851)",
                "at org.apache.hadoop.hbase.regionserver.wal.HLogSplitter$WriterThread.doRun(HLogSplitter.java:843)",
                "at org.apache.hadoop.hbase.regionserver.wal.HLogSplitter$WriterThread.run(HLogSplitter.java:813)",
                "Caused by: java.io.IOException",
                "at com.microsoft.windowsazure.storage.core.Utility.initIOException(Utility.java:493)",
                "at com.microsoft.windowsazure.storage.blob.BlobOutputStream.close(BlobOutputStream.java:282)",
                "at org.apache.hadoop.fs.azurenative.AzureNativeFileSystemStore.storeEmptyFolder(AzureNativeFileSystemStore.java:1472)",
                "... 10 more",
                "Caused by: com.microsoft.windowsazure.storage.StorageException: There is currently a lease on the blob and no lease ID was specified in the request.",
                "at com.microsoft.windowsazure.storage.StorageException.translateException(StorageException.java:163)",
                "at com.microsoft.windowsazure.storage.core.StorageRequest.materializeException(StorageRequest.java:306)",
                "at com.microsoft.windowsazure.storage.core.ExecutionEngine.executeWithRetry(ExecutionEngine.java:229)",
                "at com.microsoft.windowsazure.storage.blob.CloudBlockBlob.commitBlockList(CloudBlockBlob.java:248)",
                "at com.microsoft.windowsazure.storage.blob.BlobOutputStream.commit(BlobOutputStream.java:319)",
                "at com.microsoft.windowsazure.storage.blob.BlobOutputStream.close(BlobOutputStream.java:279)"
            ],
            "RootCause": "The root cause of the issue is a StorageException indicating that there is a lease on the blob, which prevents the log splitting process from writing to Azure Blob Storage. This is likely due to concurrent access or a previous operation that did not release the lease properly.",
            "StepsToReproduce": [
                "1. Start the HBase region server with log splitting enabled.",
                "2. Ensure that there is a blob in Azure Blob Storage that is currently leased.",
                "3. Trigger the log splitting process by writing log entries to HBase.",
                "4. Observe the IOException being thrown during the log splitting process."
            ],
            "ExpectedBehavior": "The log splitting process should complete successfully, writing log entries to Azure Blob Storage without any exceptions.",
            "ObservedBehavior": "An IOException is thrown during the log splitting process, indicating that a lease on the blob is preventing the operation from completing.",
            "Suggestions": "To resolve this issue, ensure that no other processes are holding a lease on the blob during the log splitting operation. If necessary, release the lease on the blob before attempting to write log entries. Additionally, consider implementing error handling to manage lease conflicts gracefully."
        }
    },
    {
        "filename": "HADOOP-8589.json",
        "creation_time": "2012-07-11T23:27:00.000+0000",
        "bug_report": {
            "Title": "FileAlreadyExistsException in Hadoop ViewFileSystem Initialization",
            "Description": "An exception is thrown during the initialization of the ViewFileSystem due to an attempt to create a link at a path that already exists as a directory.",
            "StackTrace": [
                "org.apache.hadoop.fs.FileAlreadyExistsException: Path /var already exists as dir; cannot create link here",
                "at org.apache.hadoop.fs.viewfs.InodeTree.createLink(InodeTree.java:244)",
                "at org.apache.hadoop.fs.viewfs.InodeTree.<init>(InodeTree.java:334)",
                "at org.apache.hadoop.fs.viewfs.ViewFileSystem$1.<init>(ViewFileSystem.java:167)",
                "at org.apache.hadoop.fs.viewfs.ViewFileSystem.initialize(ViewFileSystem.java:167)",
                "at org.apache.hadoop.fs.FileSystem.createFileSystem(FileSystem.java:2094)",
                "at org.apache.hadoop.fs.FileSystem.access$200(FileSystem.java:79)",
                "at org.apache.hadoop.fs.FileSystem$Cache.getInternal(FileSystem$Cache.java:2128)",
                "at org.apache.hadoop.fs.FileSystem$Cache.get(FileSystem.java:2110)",
                "at org.apache.hadoop.fs.FileSystem.get(FileSystem.java:290)",
                "at org.apache.hadoop.fs.viewfs.ViewFileSystemTestSetup.setupForViewFileSystem(ViewFileSystemTestSetup.java:76)",
                "at org.apache.hadoop.fs.viewfs.TestFSMainOperationsLocalFileSystem.setUp(TestFSMainOperationsLocalFileSystem.java:40)"
            ],
            "RootCause": "The root cause of the exception is that the method 'createLink' in the 'InodeTree' class is trying to create a link at a path ('/var') that already exists as a directory, which violates Hadoop's file system constraints.",
            "StepsToReproduce": [
                "Attempt to initialize the ViewFileSystem when the directory '/var' already exists.",
                "Run the test case 'TestFSMainOperationsLocalFileSystem' which triggers the setup method."
            ],
            "ExpectedBehavior": "The ViewFileSystem should initialize without throwing an exception, even if the target directory already exists.",
            "ObservedBehavior": "A FileAlreadyExistsException is thrown, preventing the successful initialization of the ViewFileSystem.",
            "Suggestions": "Check if the target path '/var' exists before attempting to create a link. Modify the 'createLink' method to handle existing directories gracefully, possibly by skipping the link creation or providing a more informative error message."
        }
    },
    {
        "filename": "HADOOP-11754.json",
        "creation_time": "2015-03-26T05:22:54.000+0000",
        "bug_report": {
            "Title": "Hadoop YARN Web Application Startup Failure Due to Signature Secret File Read Error",
            "Description": "The Hadoop YARN web application fails to start because it cannot read the signature secret file located at '/Users/sjlee/hadoop-http-auth-signature-secret'. This results in a RuntimeException, which prevents the HTTP server from initializing properly.",
            "StackTrace": [
                "javax.servlet.ServletException: java.lang.RuntimeException: Could not read signature secret file: /Users/sjlee/hadoop-http-auth-signature-secret",
                "at org.apache.hadoop.security.authentication.server.AuthenticationFilter.initializeSecretProvider(AuthenticationFilter.java:266)",
                "at org.apache.hadoop.security.authentication.server.AuthenticationFilter.init(AuthenticationFilter.java:225)",
                "at org.apache.hadoop.security.token.delegation.web.DelegationTokenAuthenticationFilter.init(DelegationTokenAuthenticationFilter.java:161)",
                "at org.apache.hadoop.yarn.server.security.http.RMAuthenticationFilter.init(RMAuthenticationFilter.java:53)",
                "at org.mortbay.jetty.servlet.FilterHolder.doStart(FilterHolder.java:97)",
                "at org.mortbay.component.AbstractLifeCycle.start(AbstractLifeCycle.java:50)",
                "at org.mortbay.jetty.servlet.ServletHandler.initialize(ServletHandler.java:713)",
                "at org.mortbay.jetty.servlet.Context.startContext(Context.java:140)",
                "at org.mortbay.jetty.webapp.WebAppContext.startContext(WebAppContext.java:1282)",
                "at org.mortbay.jetty.handler.ContextHandler.doStart(ContextHandler.java:518)",
                "at org.mortbay.jetty.webapp.WebAppContext.doStart(WebAppContext.java:499)",
                "at org.mortbay.component.AbstractLifeCycle.start(AbstractLifeCycle.java:50)",
                "at org.mortbay.jetty.handler.HandlerCollection.doStart(HandlerCollection.java:152)",
                "at org.mortbay.jetty.handler.ContextHandlerCollection.doStart(ContextHandlerCollection.java:156)",
                "at org.mortbay.component.AbstractLifeCycle.start(AbstractLifeCycle.java:50)",
                "at org.mortbay.jetty.handler.HandlerWrapper.doStart(HandlerWrapper.java:130)",
                "at org.mortbay.jetty.Server.doStart(Server.java:224)",
                "at org.mortbay.component.AbstractLifeCycle.start(AbstractLifeCycle.java:50)",
                "at org.apache.hadoop.http.HttpServer2.start(HttpServer2.java:773)",
                "at org.apache.hadoop.yarn.webapp.WebApps$Builder.start(WebApps.java:274)",
                "at org.apache.hadoop.yarn.server.resourcemanager.ResourceManager.startWepApp(ResourceManager.java:974)",
                "at org.apache.hadoop.yarn.server.resourcemanager.ResourceManager.serviceStart(ResourceManager.java:1074)",
                "at org.apache.hadoop.service.AbstractService.start(AbstractService.java:193)",
                "at org.apache.hadoop.yarn.server.resourcemanager.ResourceManager.main(ResourceManager.java:1208)",
                "Caused by: java.lang.RuntimeException: Could not read signature secret file: /Users/sjlee/hadoop-http-auth-signature-secret",
                "at org.apache.hadoop.security.authentication.util.FileSignerSecretProvider.init(FileSignerSecretProvider.java:59)",
                "at org.apache.hadoop.security.authentication.server.AuthenticationFilter.initializeSecretProvider(AuthenticationFilter.java:264)",
                "... 23 more",
                "org.apache.hadoop.yarn.webapp.WebAppException: Error starting http server",
                "at org.apache.hadoop.yarn.webapp.WebApps$Builder.start(WebApps.java:279)",
                "at org.apache.hadoop.yarn.server.resourcemanager.ResourceManager.startWepApp(ResourceManager.java:974)",
                "at org.apache.hadoop.yarn.server.resourcemanager.ResourceManager.serviceStart(ResourceManager.java:1074)",
                "at org.apache.hadoop.service.AbstractService.start(AbstractService.java:193)",
                "at org.apache.hadoop.yarn.server.resourcemanager.ResourceManager.main(ResourceManager.java:1208)",
                "Caused by: java.io.IOException: Problem in starting http server. Server handlers failed",
                "at org.apache.hadoop.http.HttpServer2.start(HttpServer2.java:785)",
                "at org.apache.hadoop.yarn.webapp.WebApps$Builder.start(WebApps.java:274)"
            ],
            "RootCause": "The root cause of the issue is the inability to read the signature secret file due to potential file permission issues or misconfiguration.",
            "StepsToReproduce": [
                "Attempt to start the Hadoop YARN web application.",
                "Ensure that the signature secret file is located at '/Users/sjlee/hadoop-http-auth-signature-secret'.",
                "Check the file permissions for the signature secret file."
            ],
            "ExpectedBehavior": "The Hadoop YARN web application should start successfully without any errors related to the signature secret file.",
            "ObservedBehavior": "The application fails to start, throwing a RuntimeException indicating that the signature secret file could not be read.",
            "Suggestions": "Verify that the signature secret file exists at the specified path and check the file permissions to ensure that the application has read access. If the file is missing, create it or update the configuration to point to the correct file location."
        }
    },
    {
        "filename": "HADOOP-8225.json",
        "creation_time": "2012-03-13T20:33:53.000+0000",
        "bug_report": {
            "Title": "SecurityException: Intercepted System.exit(-999) in DistCp",
            "Description": "A SecurityException is thrown when the DistCp tool attempts to call System.exit(-999), which is intercepted by the LauncherSecurityManager to prevent unauthorized exits in a secure environment. This issue arises during the execution of a Hadoop job that utilizes DistCp.",
            "StackTrace": [
                "java.lang.SecurityException: Intercepted System.exit(-999)",
                "at org.apache.oozie.action.hadoop.LauncherSecurityManager.checkExit(LauncherMapper.java:651)",
                "at java.lang.Runtime.exit(Runtime.java:88)",
                "at java.lang.System.exit(System.java:904)",
                "at org.apache.hadoop.tools.DistCp.main(DistCp.java:357)",
                "at sun.reflect.NativeMethodAccessorImpl.invoke0(Native Method)",
                "at sun.reflect.NativeMethodAccessorImpl.invoke(NativeMethodAccessorImpl.java:39)",
                "at sun.reflect.DelegatingMethodAccessorImpl.invoke(DelegatingMethodAccessorImpl.java:25)",
                "at java.lang.reflect.Method.invoke(Method.java:597)",
                "at org.apache.oozie.action.hadoop.LauncherMapper.map(LauncherMapper.java:394)",
                "at org.apache.hadoop.mapred.MapRunner.run(MapRunner.java:54)",
                "at org.apache.hadoop.mapred.MapTask.runOldMapper(MapTask.java:399)",
                "at org.apache.hadoop.mapred.MapTask.run(MapTask.java:334)",
                "at org.apache.hadoop.mapred.YarnChild$2.run(YarnChild.java:147)",
                "at java.security.AccessController.doPrivileged(Native Method)",
                "at javax.security.auth.Subject.doAs(Subject.java:396)",
                "at org.apache.hadoop.security.UserGroupInformation.doAs(UserGroupInformation.java:1177)",
                "at org.apache.hadoop.mapred.YarnChild.main(YarnChild.java:142)"
            ],
            "RootCause": "The root cause of the issue is the attempt by the DistCp.main method to call System.exit(-999), which is not permitted in the context of the Oozie job due to security restrictions enforced by the LauncherSecurityManager.",
            "StepsToReproduce": [
                "Run a Hadoop job that uses the DistCp tool.",
                "Ensure that the job is executed within an Oozie workflow.",
                "Observe the logs for any SecurityException related to System.exit."
            ],
            "ExpectedBehavior": "The DistCp tool should execute successfully without attempting to exit the JVM, allowing the Oozie job to complete without interruption.",
            "ObservedBehavior": "The job fails with a SecurityException, preventing the completion of the DistCp operation and causing the Oozie workflow to terminate unexpectedly.",
            "Suggestions": "Modify the DistCp implementation to avoid calling System.exit. Instead, handle exit conditions gracefully by returning appropriate exit codes or throwing exceptions that can be caught and managed by the Oozie workflow."
        }
    },
    {
        "filename": "HADOOP-10866.json",
        "creation_time": "2014-07-18T22:00:15.000+0000",
        "bug_report": {
            "Title": "IOException in TestSymlinkLocalFS.testDanglingLink due to Non-Symbolic Link",
            "Description": "The test case 'testDanglingLink' in the 'TestSymlinkLocalFS' class fails with an IOException indicating that the specified path is not a symbolic link. This issue arises when the test attempts to validate a symbolic link that does not exist or is incorrectly set up.",
            "StackTrace": [
                "java.io.IOException: Path file:/home/jenkins/jenkins-slave/workspace/PreCommit-HDFS-Build/trunk/hadoop-common-project/hadoop-common/target/test/data/RtGBheUh4y/test1/linkToFile is not a symbolic link",
                "at org.apache.hadoop.fs.FileStatus.getSymlink(FileStatus.java:266)",
                "at org.apache.hadoop.fs.TestSymlinkLocalFS.testDanglingLink(TestSymlinkLocalFS.java:163)",
                "at sun.reflect.NativeMethodAccessorImpl.invoke0(Native Method)",
                "at sun.reflect.NativeMethodAccessorImpl.invoke(NativeMethodAccessorImpl.java:39)",
                "at sun.reflect.DelegatingMethodAccessorImpl.invoke(DelegatingMethodAccessorImpl.java:25)",
                "at java.lang.reflect.Method.invoke(Method.java:597)",
                "at org.junit.runners.model.FrameworkMethod$1.runReflectiveCall(FrameworkMethod.java:47)",
                "at org.junit.internal.runners.model.ReflectiveCallable.run(ReflectiveCallable.java:12)",
                "at org.junit.runners.model.FrameworkMethod.invokeExplosively(FrameworkMethod.java:44)",
                "at org.junit.internal.runners.statements.InvokeMethod.evaluate(InvokeMethod.java:17)",
                "at org.junit.internal.runners.statements.FailOnTimeout$StatementThread.run(FailOnTimeout.java:74)"
            ],
            "RootCause": "The method 'getSymlink' in the 'FileStatus' class is throwing an IOException because the specified path is not a symbolic link. This indicates that the test setup may be incorrect or the expected symbolic link does not exist.",
            "StepsToReproduce": [
                "Navigate to the test directory: /home/jenkins/jenkins-slave/workspace/PreCommit-HDFS-Build/trunk/hadoop-common-project/hadoop-common/target/test/data/RtGBheUh4y/test1/",
                "Ensure that 'linkToFile' is created as a symbolic link pointing to a valid target.",
                "Run the test case 'TestSymlinkLocalFS.testDanglingLink'."
            ],
            "ExpectedBehavior": "The test case should successfully validate the symbolic link without throwing an IOException.",
            "ObservedBehavior": "The test case fails with an IOException indicating that the specified path is not a symbolic link.",
            "Suggestions": "Verify the setup of the symbolic link 'linkToFile' in the test directory. Ensure that it points to a valid target and is correctly created as a symbolic link. If necessary, modify the test to create the symbolic link programmatically before the test execution."
        }
    },
    {
        "filename": "HADOOP-12089.json",
        "creation_time": "2015-06-15T17:34:46.000+0000",
        "bug_report": {
            "Title": "Azure Blob Lease Exception During File Deletion",
            "Description": "An AzureException is thrown when attempting to delete a blob that is currently leased without providing a lease ID. This issue arises during the execution of the CleanerChore in HBase, which attempts to delete files that may be locked by an active lease.",
            "StackTrace": [
                "org.apache.hadoop.fs.azure.AzureException: com.microsoft.azure.storage.StorageException: There is currently a lease on the blob and no lease ID was specified in the request.",
                "at org.apache.hadoop.fs.azure.AzureNativeFileSystemStore.updateFolderLastModifiedTime(AzureNativeFileSystemStore.java:2602)",
                "at org.apache.hadoop.fs.azure.AzureNativeFileSystemStore.updateFolderLastModifiedTime(AzureNativeFileSystemStore.java:2613)",
                "at org.apache.hadoop.fs.azure.NativeAzureFileSystem.delete(NativeAzureFileSystem.java:1505)",
                "at org.apache.hadoop.fs.azure.NativeAzureFileSystem.delete(NativeAzureFileSystem.java:1437)",
                "at org.apache.hadoop.hbase.master.cleaner.CleanerChore.checkAndDeleteFiles(CleanerChore.java:256)",
                "at org.apache.hadoop.hbase.master.cleaner.CleanerChore.checkAndDeleteEntries(CleanerChore.java:157)",
                "at org.apache.hadoop.hbase.master.cleaner.CleanerChore.chore(CleanerChore.java:124)",
                "at org.apache.hadoop.hbase.Chore.run(Chore.java:80)",
                "at java.lang.Thread.run(Thread.java:745)",
                "Caused by: com.microsoft.azure.storage.StorageException: There is currently a lease on the blob and no lease ID was specified in the request.",
                "at com.microsoft.azure.storage.StorageException.translateException(StorageException.java:162)",
                "at com.microsoft.azure.storage.core.StorageRequest.materializeException(StorageRequest.java:307)",
                "at com.microsoft.azure.storage.core.ExecutionEngine.executeWithRetry(ExecutionEngine.java:177)",
                "at com.microsoft.azure.storage.blob.CloudBlob.uploadProperties(CloudBlob.java:2991)",
                "at org.apache.hadoop.fs.azure.StorageInterfaceImpl$CloudBlobWrapperImpl.uploadProperties(StorageInterfaceImpl.java:372)",
                "at org.apache.hadoop.fs.azure.AzureNativeFileSystemStore.updateFolderLastModifiedTime(AzureNativeFileSystemStore.java:2597)"
            ],
            "RootCause": "The operation failed because the blob is currently leased, and no lease ID was provided in the delete request. This prevents modification or deletion of the blob until the lease is released or a valid lease ID is supplied.",
            "StepsToReproduce": [
                "1. Ensure a blob in Azure Storage is leased.",
                "2. Trigger the CleanerChore in HBase that attempts to delete or modify the leased blob.",
                "3. Observe the AzureException being thrown."
            ],
            "ExpectedBehavior": "The CleanerChore should either skip the deletion of the leased blob or provide a valid lease ID to perform the operation.",
            "ObservedBehavior": "An AzureException is thrown indicating that the blob cannot be modified or deleted due to an active lease without a lease ID.",
            "Suggestions": "Implement a check in the CleanerChore to determine if a blob is leased before attempting to delete it. If it is leased, either skip the deletion or log a warning. Additionally, consider providing a mechanism to specify a lease ID if the operation must proceed."
        }
    },
    {
        "filename": "HADOOP-11934.json",
        "creation_time": "2015-05-07T00:38:53.000+0000",
        "bug_report": {
            "Title": "Hadoop Credential Provider Initialization Failure",
            "Description": "The application encounters an error during the initialization of the JavaKeyStoreProvider, which is part of the Hadoop security framework. This issue arises when attempting to obtain a FileSystem instance, indicating potential misconfiguration of credential providers.",
            "StackTrace": [
                "at org.apache.hadoop.fs.FileSystem.get(FileSystem.java:370)",
                "at org.apache.hadoop.fs.Path.getFileSystem(Path.java:296)",
                "at org.apache.hadoop.security.alias.JavaKeyStoreProvider.<init>(JavaKeyStoreProvider.java:88)",
                "at org.apache.hadoop.security.alias.JavaKeyStoreProvider.<init>(JavaKeyStoreProvider.java:65)",
                "at org.apache.hadoop.security.alias.JavaKeyStoreProvider$Factory.createProvider(JavaKeyStoreProvider.java:291)",
                "at org.apache.hadoop.security.alias.CredentialProviderFactory.getProviders(CredentialProviderFactory.java:58)",
                "at org.apache.hadoop.conf.Configuration.getPasswordFromCredentialProviders(Configuration.java:1863)",
                "at org.apache.hadoop.conf.Configuration.getPassword(Configuration.java:1843)",
                "at org.apache.hadoop.security.LdapGroupsMapping.getPassword(LdapGroupsMapping.java:386)",
                "at org.apache.hadoop.security.LdapGroupsMapping.setConf(LdapGroupsMapping.java:349)",
                "at org.apache.hadoop.util.ReflectionUtils.setConf(ReflectionUtils.java:73)",
                "at org.apache.hadoop.util.ReflectionUtils.newInstance(ReflectionUtils.java:133)",
                "at org.apache.hadoop.security.Groups.<init>(Groups.java:70)",
                "at org.apache.hadoop.security.Groups.<init>(Groups.java:66)",
                "at org.apache.hadoop.security.Groups.getUserToGroupsMappingService(Groups.java:280)",
                "at org.apache.hadoop.security.UserGroupInformation.initialize(UserGroupInformation.java:283)",
                "at org.apache.hadoop.security.UserGroupInformation.ensureInitialized(UserGroupInformation.java:260)",
                "at org.apache.hadoop.security.UserGroupInformation.loginUserFromSubject(UserGroupInformation.java:804)",
                "at org.apache.hadoop.security.UserGroupInformation.getLoginUser(UserGroupInformation.java:774)",
                "at org.apache.hadoop.security.UserGroupInformation.getCurrentUser(UserGroupInformation.java:647)",
                "at org.apache.hadoop.fs.FileSystem$Cache$Key.<init>(FileSystem.java:2753)",
                "at org.apache.hadoop.fs.FileSystem$Cache$Key.<init>(FileSystem.java:2745)",
                "at org.apache.hadoop.fs.FileSystem$Cache.get(FileSystem.java:2611)"
            ],
            "RootCause": "Misconfiguration of credential providers in Hadoop, preventing the JavaKeyStoreProvider from initializing correctly.",
            "StepsToReproduce": [
                "1. Configure Hadoop with a credential provider.",
                "2. Attempt to access a FileSystem instance that requires credentials.",
                "3. Observe the error during the initialization of the JavaKeyStoreProvider."
            ],
            "ExpectedBehavior": "The application should successfully initialize the JavaKeyStoreProvider and obtain the necessary FileSystem instance without errors.",
            "ObservedBehavior": "The application fails to initialize the JavaKeyStoreProvider, resulting in an error when attempting to access the FileSystem.",
            "Suggestions": "Review the configuration settings for credential providers in Hadoop. Ensure that the paths to the keystore and any required credentials are correctly specified. Additionally, verify that the necessary permissions are granted for accessing the keystore."
        }
    },
    {
        "filename": "HADOOP-11722.json",
        "creation_time": "2015-03-16T21:39:07.000+0000",
        "bug_report": {
            "Title": "RuntimeException in ZKDelegationTokenSecretManager: NoNodeException on Token Removal",
            "Description": "The application encountered a RuntimeException while attempting to remove a stored token from ZooKeeper. The error indicates that the token being removed does not exist in the ZooKeeper node, leading to a NoNodeException.",
            "StackTrace": [
                "java.lang.RuntimeException: Could not remove Stored Token ZKDTSMDelegationToken_28",
                "at org.apache.hadoop.security.token.delegation.ZKDelegationTokenSecretManager.removeStoredToken(ZKDelegationTokenSecretManager.java:770)",
                "at org.apache.hadoop.security.token.delegation.AbstractDelegationTokenSecretManager.removeExpiredToken(AbstractDelegationTokenSecretManager.java:605)",
                "at org.apache.hadoop.security.token.delegation.AbstractDelegationTokenSecretManager.access$400(AbstractDelegationTokenSecretManager.java:54)",
                "at org.apache.hadoop.security.token.delegation.AbstractDelegationTokenSecretManager$ExpiredTokenRemover.run(AbstractDelegationTokenSecretManager.java:656)",
                "at java.lang.Thread.run(Thread.java:745)",
                "Caused by: org.apache.zookeeper.KeeperException$NoNodeException: KeeperErrorCode = NoNode for /zkdtsm/ZKDTSMRoot/ZKDTSMTokensRoot/DT_28",
                "at org.apache.zookeeper.KeeperException.create(KeeperException.java:111)",
                "at org.apache.zookeeper.KeeperException.create(KeeperException.java:51)",
                "at org.apache.zookeeper.ZooKeeper.delete(ZooKeeper.java:873)",
                "at org.apache.curator.framework.imps.DeleteBuilderImpl$5.call(DeleteBuilderImpl.java:238)",
                "at org.apache.curator.framework.imps.DeleteBuilderImpl$5.call(DeleteBuilderImpl.java:233)",
                "at org.apache.curator.RetryLoop.callWithRetry(RetryLoop.java:107)",
                "at org.apache.curator.framework.imps.DeleteBuilderImpl.pathInForeground(DeleteBuilderImpl.java:230)",
                "at org.apache.curator.framework.imps.DeleteBuilderImpl.forPath(DeleteBuilderImpl.java:214)",
                "at org.apache.curator.framework.imps.DeleteBuilderImpl.forPath(DeleteBuilderImpl.java:41)",
                "at org.apache.hadoop.security.token.delegation.ZKDelegationTokenSecretManager.removeStoredToken(ZKDelegationTokenSecretManager.java:764)",
                "... 4 more"
            ],
            "RootCause": "The root cause of the issue is that the application attempted to delete a ZooKeeper node that does not exist, resulting in a NoNodeException. This indicates that the token may have already been removed or was never created.",
            "StepsToReproduce": [
                "Attempt to remove a stored token from the ZKDelegationTokenSecretManager.",
                "Ensure that the token being removed has already been deleted or was never created.",
                "Monitor the logs for RuntimeException related to token removal."
            ],
            "ExpectedBehavior": "The expected behavior is that the token removal process should complete successfully without throwing an exception, even if the token does not exist.",
            "ObservedBehavior": "The observed behavior is that a RuntimeException is thrown, indicating that the token could not be removed due to a NoNodeException.",
            "Suggestions": "To resolve this issue, implement a check in the removeStoredToken method to verify if the token exists in ZooKeeper before attempting to delete it. This will prevent the RuntimeException from occurring when trying to remove a non-existent token."
        }
    },
    {
        "filename": "HADOOP-15331.json",
        "creation_time": "2018-03-21T01:15:56.000+0000",
        "bug_report": {
            "Title": "WstxIOException: Stream closed during Configuration parsing",
            "Description": "The application encounters a WstxIOException indicating that a stream has been closed while attempting to parse configuration files in a Hadoop application. This issue arises during the initialization of the ResourceManager and affects the ability to load necessary configurations.",
            "StackTrace": [
                "com.ctc.wstx.exc.WstxIOException: Stream closed",
                "at com.ctc.wstx.stax.WstxInputFactory.doCreateSR(WstxInputFactory.java:578)",
                "at com.ctc.wstx.stax.WstxInputFactory.createSR(WstxInputFactory.java:633)",
                "at org.apache.hadoop.conf.Configuration.parse(Configuration.java:2803)",
                "at org.apache.hadoop.conf.Configuration.loadResource(Configuration.java:2853)",
                "at org.apache.hadoop.conf.Configuration.loadResources(Configuration.java:2817)",
                "at org.apache.hadoop.conf.Configuration.getProps(Configuration.java:2689)",
                "at org.apache.hadoop.security.authorize.ServiceAuthorizationManager.refreshWithLoadedConfiguration(ServiceAuthorizationManager.java:161)",
                "at org.apache.hadoop.ipc.Server.refreshServiceAclWithLoadedConfiguration(Server.java:607)",
                "at org.apache.hadoop.yarn.server.resourcemanager.AdminService.refreshServiceAcls(AdminService.java:586)",
                "at org.apache.hadoop.yarn.server.resourcemanager.AdminService.startServer(AdminService.java:188)",
                "at org.apache.hadoop.yarn.server.resourcemanager.AdminService.serviceStart(AdminService.java:165)",
                "at org.apache.hadoop.service.AbstractService.start(AbstractService.java:194)",
                "at org.apache.hadoop.service.CompositeService.serviceStart(AbstractService.java:121)",
                "at org.apache.hadoop.yarn.server.resourcemanager.ResourceManager.serviceStart(ResourceManager.java:1231)",
                "at org.apache.hadoop.service.AbstractService.start(AbstractService.java:194)",
                "at org.apache.hadoop.yarn.server.resourcemanager.ResourceManager.main(ResourceManager.java:1421)"
            ],
            "RootCause": "The root cause of the issue is an attempt to read from a closed stream in the Configuration parsing process, specifically in the org.apache.hadoop.conf.Configuration.parse method.",
            "StepsToReproduce": [
                "Start the Hadoop ResourceManager service.",
                "Ensure that the configuration files are correctly set up.",
                "Monitor the logs for any errors during the initialization phase."
            ],
            "ExpectedBehavior": "The ResourceManager should start successfully, loading all necessary configurations without any errors.",
            "ObservedBehavior": "The ResourceManager fails to start, logging a WstxIOException indicating that the stream is closed, preventing the loading of configuration files.",
            "Suggestions": "Check the configuration files for any issues that may cause the stream to close prematurely. Ensure that the input stream used for configuration loading is not being closed before the parsing is complete. Additionally, review the code in the Configuration class to ensure proper handling of input streams."
        }
    },
    {
        "filename": "HADOOP-14062.json",
        "creation_time": "2016-12-20T00:35:48.000+0000",
        "bug_report": {
            "Title": "EOFException during RPC call in Hadoop Application",
            "Description": "An EOFException is thrown when the application attempts to communicate with the ResourceManager, indicating that the end of the file was reached unexpectedly. This typically suggests a problem with the network connection or the server being unavailable.",
            "StackTrace": [
                "java.io.EOFException: End of File Exception between local host is: \"<application_master_host>/<ip_addr>\"; destination host is: \"<rm_host>\":8030; : java.io.EOFException; For more details see:  http://wiki.apache.org/hadoop/EOFException",
                "at sun.reflect.NativeConstructorAccessorImpl.newInstance0(Native Method)",
                "at sun.reflect.NativeConstructorAccessorImpl.newInstance(NativeConstructorAccessorImpl.java:62)",
                "at sun.reflect.DelegatingConstructorAccessorImpl.newInstance(DelegatingConstructorAccessorImpl.java:45)",
                "at java.lang.reflect.Constructor.newInstance(Constructor.java:422)",
                "at org.apache.hadoop.net.NetUtils.wrapWithMessage(NetUtils.java:801)",
                "at org.apache.hadoop.net.NetUtils.wrapException(NetUtils.java:765)",
                "at org.apache.hadoop.ipc.Client.getRpcResponse(Client.java:1486)",
                "at org.apache.hadoop.ipc.Client.call(Client.java:1428)",
                "at org.apache.hadoop.ipc.Client.call(Client.java:1338)",
                "at org.apache.hadoop.ipc.ProtobufRpcEngine$Invoker.invoke(ProtobufRpcEngine.java:227)",
                "at org.apache.hadoop.ipc.ProtobufRpcEngine$Invoker.invoke(ProtobufRpcEngine.java:116)",
                "at com.sun.proxy.$Proxy80.allocate(Unknown Source)",
                "at org.apache.hadoop.yarn.api.impl.pb.client.ApplicationMasterProtocolPBClientImpl.allocate(ApplicationMasterProtocolPBClientImpl.java:77)",
                "at sun.reflect.NativeMethodAccessorImpl.invoke0(Native Method)",
                "at sun.reflect.NativeMethodAccessorImpl.invoke(NativeMethodAccessorImpl.java:62)",
                "at sun.reflect.DelegatingMethodAccessorImpl.invoke(DelegatingMethodAccessorImpl.java:43)",
                "at java.lang.reflect.Method.invoke(Method.java:497)",
                "at org.apache.hadoop.io.retry.RetryInvocationHandler.invokeMethod(RetryInvocationHandler.java:398)",
                "at org.apache.hadoop.io.retry.RetryInvocationHandler$Call.invokeMethod(RetryInvocationHandler.java:163)",
                "at org.apache.hadoop.io.retry.RetryInvocationHandler$Call.invokeOnce(RetryInvocationHandler.java:95)",
                "at org.apache.hadoop.io.retry.RetryInvocationHandler.invoke(RetryInvocationHandler.java:335)",
                "at com.sun.proxy.$Proxy81.allocate(Unknown Source)",
                "at org.apache.hadoop.mapreduce.v2.app.rm.RMContainerRequestor.makeRemoteRequest(RMContainerRequestor.java:204)",
                "at org.apache.hadoop.mapreduce.v2.app.rm.RMContainerAllocator.getResources(RMContainerAllocator.java:735)",
                "at org.apache.hadoop.mapreduce.v2.app.rm.RMContainerAllocator.heartbeat(RMContainerAllocator.java:269)",
                "at org.apache.hadoop.mapreduce.v2.app.rm.RMCommunicator$AllocatorRunnable.run(RMCommunicator.java:281)",
                "at java.lang.Thread.run(Thread.java:745)",
                "Caused by: java.io.EOFException",
                "at java.io.DataInputStream.readInt(DataInputStream.java:392)",
                "at org.apache.hadoop.ipc.Client$IpcStreams.readResponse(Client.java:1785)",
                "at org.apache.hadoop.ipc.Client$Connection.receiveRpcResponse(Client.java:1156)",
                "at org.apache.hadoop.ipc.Client$Connection.run(Client.java:1053)"
            ],
            "RootCause": "The EOFException is likely caused by network issues or the ResourceManager being unavailable during the RPC call.",
            "StepsToReproduce": [
                "Start the Hadoop application and attempt to allocate resources from the ResourceManager.",
                "Ensure that the ResourceManager is running and accessible.",
                "Monitor the network connection between the application and the ResourceManager."
            ],
            "ExpectedBehavior": "The application should successfully communicate with the ResourceManager and allocate resources without throwing an EOFException.",
            "ObservedBehavior": "The application throws an EOFException, indicating a failure to receive a response from the ResourceManager.",
            "Suggestions": "Investigate the network connectivity between the application and the ResourceManager. Check the ResourceManager logs for any errors or indications of unavailability. Review the implementation of the Client and Connection classes, particularly the getRpcResponse method, to ensure proper handling of network interruptions."
        }
    },
    {
        "filename": "HADOOP-11149.json",
        "creation_time": "2014-09-27T16:37:06.000+0000",
        "bug_report": {
            "Title": "Timeout Exception in ZKFailoverController during Graceful Failover",
            "Description": "A timeout exception occurs in the ZKFailoverController when attempting to perform a graceful failover, indicating potential issues with network connectivity, configuration, or resource contention.",
            "StackTrace": [
                "java.lang.Exception: test timed out after 25000 milliseconds",
                "at java.lang.Object.wait(Native Method)",
                "at org.apache.hadoop.ha.ZKFailoverController.waitForActiveAttempt(ZKFailoverController.java:467)",
                "at org.apache.hadoop.ha.ZKFailoverController.doGracefulFailover(ZKFailoverController.java:657)",
                "at org.apache.hadoop.ha.ZKFailoverController.access$400(ZKFailoverController.java:61)",
                "at org.apache.hadoop.ha.ZKFailoverController$3.run(ZKFailoverController.java:602)",
                "at org.apache.hadoop.ha.ZKFailoverController$3.run(ZKFailoverController.java:599)",
                "at java.security.AccessController.doPrivileged(Native Method)",
                "at javax.security.auth.Subject.doAs(Subject.java:415)",
                "at org.apache.hadoop.security.UserGroupInformation.doAs(UserGroupInformation.java:1621)",
                "at org.apache.hadoop.ha.ZKFailoverController.gracefulFailoverToYou(ZKFailoverController.java:599)",
                "at org.apache.hadoop.ha.ZKFCRpcServer.gracefulFailover(ZKFCRpcServer.java:94)",
                "at org.apache.hadoop.ha.TestZKFailoverController.testGracefulFailover(TestZKFailoverController.java:448)"
            ],
            "RootCause": "The timeout may be caused by network issues, configuration problems, resource contention, or bugs in the implementation of the graceful failover process.",
            "StepsToReproduce": [
                "Set up a Hadoop cluster with ZKFailoverController enabled.",
                "Trigger a graceful failover while monitoring network conditions.",
                "Observe the behavior of the failover process and check for timeout exceptions."
            ],
            "ExpectedBehavior": "The graceful failover should complete successfully within the specified timeout period without throwing exceptions.",
            "ObservedBehavior": "The test fails with a timeout exception after 25000 milliseconds, indicating that the graceful failover did not complete in time.",
            "Suggestions": "Investigate network connectivity and configuration settings for the ZKFailoverController. Check for resource contention on the nodes involved in the failover process. Review logs for any additional errors or warnings that may provide insight into the failure."
        }
    },
    {
        "filename": "HADOOP-15059.json",
        "creation_time": "2017-11-21T20:54:52.000+0000",
        "bug_report": {
            "Title": "RuntimeException: Unable to determine current user due to IOException",
            "Description": "The application encounters a RuntimeException indicating that it is unable to determine the current user. This issue arises from an IOException caused by an unknown version in the token storage file while attempting to read user credentials.",
            "StackTrace": [
                "java.lang.RuntimeException: Unable to determine current user",
                "at org.apache.hadoop.conf.Configuration$Resource.getRestrictParserDefault(Configuration.java:254)",
                "at org.apache.hadoop.conf.Configuration$Resource.<init>(Configuration.java:220)",
                "at org.apache.hadoop.conf.Configuration$Resource.<init>(Configuration.java:212)",
                "at org.apache.hadoop.conf.Configuration.addResource(Configuration.java:888)",
                "at org.apache.hadoop.mapreduce.v2.app.MRAppMaster.main(MRAppMaster.java:1638)",
                "Caused by: java.io.IOException: Exception reading /tmp/nm-local-dir/usercache/jdu/appcache/application_1511295641738_0003/container_e03_1511295641738_0003_01_000001/container_tokens",
                "at org.apache.hadoop.security.Credentials.readTokenStorageFile(Credentials.java:208)",
                "at org.apache.hadoop.security.UserGroupInformation.loginUserFromSubject(UserGroupInformation.java:907)",
                "at org.apache.hadoop.security.UserGroupInformation.getLoginUser(UserGroupInformation.java:820)",
                "at org.apache.hadoop.security.UserGroupInformation.getCurrentUser(UserGroupInformation.java:689)",
                "at org.apache.hadoop.conf.Configuration$Resource.getRestrictParserDefault(Configuration.java:252)",
                "... 4 more",
                "Caused by: java.io.IOException: Unknown version 1 in token storage.",
                "at org.apache.hadoop.security.Credentials.readTokenStorageStream(Credentials.java:226)",
                "at org.apache.hadoop.security.Credentials.readTokenStorageFile(Credentials.java:205)"
            ],
            "RootCause": "IOException due to an unknown version in the token storage file while reading user credentials.",
            "StepsToReproduce": [
                "Run the application that utilizes Hadoop's MRAppMaster.",
                "Ensure that the token storage file located at /tmp/nm-local-dir/usercache/jdu/appcache/application_1511295641738_0003/container_e03_1511295641738_0003_01_000001/container_tokens is present.",
                "Attempt to access the current user information."
            ],
            "ExpectedBehavior": "The application should successfully determine the current user without throwing an exception.",
            "ObservedBehavior": "The application throws a RuntimeException indicating it is unable to determine the current user due to an IOException related to the token storage file.",
            "Suggestions": "Check the version of the token storage file and ensure it is compatible with the current Hadoop version. If the file is corrupted or in an unsupported format, consider regenerating the token storage file. Additionally, verify the permissions and accessibility of the token storage file."
        }
    },
    {
        "filename": "HADOOP-15307.json",
        "creation_time": "2018-03-12T14:56:59.000+0000",
        "bug_report": {
            "Title": "UnsupportedOperationException: Unsupported verifier flavor AUTH_SYS in Hadoop RPC",
            "Description": "The application throws an UnsupportedOperationException when attempting to read a verifier flavor during RPC communication. This issue arises specifically with the AUTH_SYS verifier flavor, which is not supported in the current configuration or version of Hadoop being used.",
            "StackTrace": [
                "java.lang.UnsupportedOperationException: Unsupported verifier flavor AUTH_SYS",
                "at org.apache.hadoop.oncrpc.security.Verifier.readFlavorAndVerifier(Verifier.java:45)",
                "at org.apache.hadoop.oncrpc.RpcDeniedReply.read(RpcDeniedReply.java:50)",
                "at org.apache.hadoop.oncrpc.RpcReply.read(RpcReply.java:67)",
                "at org.apache.hadoop.oncrpc.SimpleUdpClient.run(SimpleUdpClient.java:71)",
                "at org.apache.hadoop.oncrpc.RpcProgram.register(RpcProgram.java:130)",
                "at org.apache.hadoop.oncrpc.RpcProgram.register(RpcProgram.java:101)",
                "at org.apache.hadoop.mount.MountdBase.start(MountdBase.java:83)",
                "at org.apache.hadoop.hdfs.nfs.nfs3.Nfs3.startServiceInternal(Nfs3.java:56)",
                "at org.apache.hadoop.hdfs.nfs.nfs3.Nfs3.startService(Nfs3.java:69)",
                "at org.apache.hadoop.hdfs.nfs.nfs3.PrivilegedNfsGatewayStarter.start(PrivilegedNfsGatewayStarter.java:60)",
                "at sun.reflect.NativeMethodAccessorImpl.invoke0(Native Method)",
                "at sun.reflect.NativeMethodAccessorImpl.invoke(NativeMethodAccessorImpl.java:62)",
                "at sun.reflect.DelegatingMethodAccessorImpl.invoke(DelegatingMethodAccessorImpl.java:43)",
                "at java.lang.reflect.Method.invoke(Method.java:498)",
                "at org.apache.commons.daemon.support.DaemonLoader.start(DaemonLoader.java:243)"
            ],
            "RootCause": "The UnsupportedOperationException is caused by the application attempting to use an unsupported verifier flavor (AUTH_SYS) in the RPC communication. This may be due to misconfiguration or an incompatible version of Hadoop.",
            "StepsToReproduce": [
                "Configure the Hadoop environment to use AUTH_SYS verifier flavor.",
                "Attempt to start the NFS service using the configured settings.",
                "Observe the logs for the UnsupportedOperationException."
            ],
            "ExpectedBehavior": "The NFS service should start successfully without throwing any exceptions related to unsupported verifier flavors.",
            "ObservedBehavior": "The NFS service fails to start, throwing an UnsupportedOperationException indicating that AUTH_SYS is an unsupported verifier flavor.",
            "Suggestions": "1. Check the Hadoop configuration files for any settings related to RPC and verifier flavors. Ensure that AUTH_SYS is supported in the current version of Hadoop. 2. Verify that all library versions are compatible with the Hadoop version being used. 3. Review the official Hadoop documentation for any notes on verifier flavors and RPC configurations. 4. Seek assistance from the Hadoop community or forums if the issue persists."
        }
    },
    {
        "filename": "HADOOP-11446.json",
        "creation_time": "2014-12-23T22:15:23.000+0000",
        "bug_report": {
            "Title": "OutOfMemoryError: Unable to Create New Native Thread",
            "Description": "The application encounters an OutOfMemoryError when attempting to create new threads, leading to failure in executing concurrent tasks, particularly during file uploads to S3.",
            "StackTrace": [
                "Exception in thread \"main\" java.lang.OutOfMemoryError: unable to create new native thread",
                "at java.lang.Thread.start0(Native Method)",
                "at java.lang.Thread.start(Thread.java:713)",
                "at java.util.concurrent.ThreadPoolExecutor.addWorker(ThreadPoolExecutor.java:949)",
                "at java.util.concurrent.ThreadPoolExecutor.execute(ThreadPoolExecutor.java:1360)",
                "at java.util.concurrent.AbstractExecutorService.submit(AbstractExecutorService.java:132)",
                "at com.amazonaws.services.s3.transfer.internal.UploadMonitor.<init>(UploadMonitor.java:129)",
                "at com.amazonaws.services.s3.transfer.TransferManager.upload(TransferManager.java:449)",
                "at com.amazonaws.services.s3.transfer.TransferManager.upload(TransferManager.java:382)",
                "at org.apache.hadoop.fs.s3a.S3AOutputStream.close(S3AOutputStream.java:127)",
                "at org.apache.hadoop.fs.FSDataOutputStream$PositionCache.close(FSDataOutputStream.java:72)",
                "at org.apache.hadoop.fs.FSDataOutputStream.close(FSDataOutputStream.java:106)",
                "at org.apache.hadoop.io.IOUtils.copyBytes(IOUtils.java:54)",
                "at org.apache.hadoop.io.IOUtils.copyBytes(IOUtils.java:112)",
                "at org.apache.hadoop.fs.FileUtil.copy(FileUtil.java:366)",
                "at org.apache.hadoop.fs.FileUtil.copy(FileUtil.java:356)",
                "at org.apache.hadoop.fs.FileUtil.copy(FileUtil.java:356)",
                "at org.apache.hadoop.fs.FileUtil.copy(FileUtil.java:338)",
                "at org.apache.hadoop.hbase.snapshot.ExportSnapshot.run(ExportSnapshot.java:791)",
                "at org.apache.hadoop.util.ToolRunner.run(ToolRunner.java:70)",
                "at org.apache.hadoop.hbase.snapshot.ExportSnapshot.innerMain(ExportSnapshot.java:882)",
                "at org.apache.hadoop.hbase.snapshot.ExportSnapshot.main(ExportSnapshot.java:886)"
            ],
            "RootCause": "The application has exhausted the system's ability to create new threads, likely due to high concurrency levels or insufficient memory allocation for the JVM.",
            "StepsToReproduce": [
                "Run the application with a high number of concurrent file uploads to S3.",
                "Monitor the system's thread usage and memory allocation during the operation."
            ],
            "ExpectedBehavior": "The application should successfully create new threads and complete the file upload process without encountering memory issues.",
            "ObservedBehavior": "The application fails with an OutOfMemoryError, preventing new threads from being created, which halts the upload process.",
            "Suggestions": "Consider increasing the JVM memory allocation (e.g., using -Xmx flag), reducing the number of concurrent uploads, and reviewing thread management practices to ensure efficient resource usage."
        }
    },
    {
        "filename": "HADOOP-12689.json",
        "creation_time": "2016-01-04T23:30:49.000+0000",
        "bug_report": {
            "Title": "IOException: /test doesn't exist in S3 File System",
            "Description": "An IOException is thrown when attempting to access the path '/test' in the S3 file system, indicating that the specified directory or file does not exist. This issue occurs during the execution of a Hadoop job that involves copying files.",
            "StackTrace": [
                "java.io.IOException: /test doesn't exist",
                "at org.apache.hadoop.fs.s3.Jets3tFileSystemStore.get(Jets3tFileSystemStore.java:170)",
                "at org.apache.hadoop.fs.s3.Jets3tFileSystemStore.retrieveINode(Jets3tFileSystemStore.java:221)",
                "at sun.reflect.NativeMethodAccessorImpl.invoke0(Native Method)",
                "at sun.reflect.NativeMethodAccessorImpl.invoke(NativeMethodAccessorImpl.java:57)",
                "at sun.reflect.DelegatingMethodAccessorImpl.invoke(DelegatingMethodAccessorImpl.java:43)",
                "at java.lang.reflect.Method.invoke(Method.java:606)",
                "at org.apache.hadoop.io.retry.RetryInvocationHandler.invokeMethod(RetryInvocationHandler.java:187)",
                "at org.apache.hadoop.io.retry.RetryInvocationHandler.invoke(RetryInvocationHandler.java:102)",
                "at com.sun.proxy.$Proxy17.retrieveINode(Unknown Source)",
                "at org.apache.hadoop.fs.s3.S3FileSystem.getFileStatus(S3FileSystem.java:340)",
                "at org.apache.hadoop.tools.mapred.CopyMapper.map(CopyMapper.java:230)",
                "at org.apache.hadoop.tools.mapred.CopyMapper.map(CopyMapper.java:50)",
                "at org.apache.hadoop.mapreduce.Mapper.run(Mapper.java:146)",
                "at org.apache.hadoop.mapred.MapTask.runNewMapper(MapTask.java:787)",
                "at org.apache.hadoop.mapred.MapTask.run(MapTask.java:341)",
                "at org.apache.hadoop.mapred.YarnChild$2.run(YarnChild.java:164)",
                "at java.security.AccessController.doPrivileged(Native Method)",
                "at javax.security.auth.Subject.doAs(Subject.java:415)",
                "at org.apache.hadoop.security.UserGroupInformation.doAs(UserGroupInformation.java:1657)",
                "at org.apache.hadoop.mapred.YarnChild.main(YarnChild.java:158)"
            ],
            "RootCause": "The specified path '/test' does not exist in the S3 file system, leading to an IOException when the Hadoop job attempts to access it.",
            "StepsToReproduce": [
                "Set up a Hadoop job that attempts to copy files from the S3 path '/test'.",
                "Run the job and observe the output."
            ],
            "ExpectedBehavior": "The Hadoop job should successfully access the files in the specified S3 path and complete without errors.",
            "ObservedBehavior": "The job fails with an IOException indicating that the path '/test' does not exist.",
            "Suggestions": "Verify that the S3 path '/test' exists and is accessible. If it does not exist, create the necessary directory or file in the S3 bucket. Additionally, check the configuration settings for the S3 file system to ensure they are correct."
        }
    },
    {
        "filename": "HADOOP-13132.json",
        "creation_time": "2016-05-11T11:42:30.000+0000",
        "bug_report": {
            "Title": "ClassCastException during Key Decryption in Hadoop",
            "Description": "A ClassCastException occurs when attempting to cast an AuthenticationException to a GeneralSecurityException during the decryption of an encrypted key in Hadoop's KMS client provider.",
            "StackTrace": [
                "java.lang.ClassCastException: org.apache.hadoop.security.authentication.client.AuthenticationException cannot be cast to java.security.GeneralSecurityException",
                "at org.apache.hadoop.crypto.key.kms.LoadBalancingKMSClientProvider.decryptEncryptedKey(LoadBalancingKMSClientProvider.java:189)",
                "at org.apache.hadoop.crypto.key.KeyProviderCryptoExtension.decryptEncryptedKey(KeyProviderCryptoExtension.java:388)",
                "at org.apache.hadoop.hdfs.DFSClient.decryptEncryptedDataEncryptionKey(DFSClient.java:1419)",
                "at org.apache.hadoop.hdfs.DFSClient.createWrappedOutputStream(DFSClient.java:1521)",
                "at org.apache.hadoop.fs.Hdfs.createInternal(Hdfs.java:108)",
                "at org.apache.hadoop.fs.Hdfs.createInternal(Hdfs.java:59)",
                "at org.apache.hadoop.fs.AbstractFileSystem.create(AbstractFileSystem.java:577)",
                "at org.apache.hadoop.fs.FileContext$3.next(FileContext.java:683)",
                "at org.apache.hadoop.fs.FileContext$3.next(FileContext.java:679)",
                "at org.apache.hadoop.fs.FSLinkResolver.resolve(FSLinkResolver.java:90)",
                "at org.apache.hadoop.fs.FileContext.create(FileContext.java:679)",
                "at org.apache.hadoop.yarn.logaggregation.AggregatedLogFormat$LogWriter$1.run(AggregatedLogFormat.java:382)",
                "at org.apache.hadoop.yarn.logaggregation.AggregatedLogFormat$LogWriter$1.run(AggregatedLogFormat.java:377)",
                "at java.security.AccessController.doPrivileged(Native Method)",
                "at javax.security.auth.Subject.doAs(Subject.java:422)",
                "at org.apache.hadoop.security.UserGroupInformation.doAs(UserGroupInformation.java:1671)",
                "at org.apache.hadoop.yarn.logaggregation.AggregatedLogFormat$LogWriter.<init>(AggregatedLogFormat.java:376)",
                "at org.apache.hadoop.yarn.server.nodemanager.containermanager.logaggregation.AppLogAggregatorImpl.uploadLogsForContainers(AppLogAggregatorImpl.java:246)",
                "at org.apache.hadoop.yarn.server.nodemanager.containermanager.logaggregation.AppLogAggregatorImpl.doAppLogAggregation(AppLogAggregatorImpl.java:456)",
                "at org.apache.hadoop.yarn.server.nodemanager.containermanager.logaggregation.AppLogAggregatorImpl.run(AppLogAggregatorImpl.java:421)",
                "at org.apache.hadoop.yarn.server.nodemanager.containermanager.logaggregation.LogAggregationService$2.run(LogAggregationService.java:384)",
                "at java.util.concurrent.ThreadPoolExecutor.runWorker(ThreadPoolExecutor.java:1142)",
                "at java.util.concurrent.ThreadPoolExecutor$Worker.run(ThreadPoolExecutor.java:617)",
                "at java.lang.Thread.run(Thread.java:745)"
            ],
            "RootCause": "The root cause of the issue is a ClassCastException occurring due to an attempt to cast an AuthenticationException to a GeneralSecurityException, which is not a valid cast.",
            "StepsToReproduce": [
                "Attempt to decrypt an encrypted key using the LoadBalancingKMSClientProvider.",
                "Ensure that the key being decrypted is associated with an AuthenticationException.",
                "Observe the logs for the ClassCastException."
            ],
            "ExpectedBehavior": "The decryption process should handle exceptions correctly without throwing a ClassCastException, allowing for proper error handling and logging.",
            "ObservedBehavior": "A ClassCastException is thrown, indicating a type mismatch in exception handling during the decryption process.",
            "Suggestions": "Review the exception handling logic in LoadBalancingKMSClientProvider to ensure that AuthenticationException is not cast to GeneralSecurityException. Check for library compatibility and consult the documentation for proper exception handling practices. Consider adding debugging logs to trace the flow of exceptions."
        }
    },
    {
        "filename": "HADOOP-15121.json",
        "creation_time": "2017-12-15T07:41:39.000+0000",
        "bug_report": {
            "Title": "NullPointerException in DecayRpcScheduler MetricsProxy",
            "Description": "A NullPointerException is thrown in the DecayRpcScheduler's MetricsProxy class when attempting to retrieve metrics. This issue occurs during the initialization of the NameNode RPC server, which is critical for the Hadoop HDFS operation.",
            "StackTrace": [
                "java.lang.NullPointerException",
                "at org.apache.hadoop.ipc.DecayRpcScheduler$MetricsProxy.getMetrics(DecayRpcScheduler.java:781)",
                "at org.apache.hadoop.metrics2.impl.MetricsSourceAdapter.getMetrics(MetricsSourceAdapter.java:199)",
                "at org.apache.hadoop.metrics2.impl.MetricsSourceAdapter.updateJmxCache(MetricsSourceAdapter.java:182)",
                "at org.apache.hadoop.metrics2.impl.MetricsSourceAdapter.getMBeanInfo(MetricsSourceAdapter.java:155)",
                "at com.sun.jmx.interceptor.DefaultMBeanServerInterceptor.getNewMBeanClassName(DefaultMBeanServerInterceptor.java:333)",
                "at com.sun.jmx.interceptor.DefaultMBeanServerInterceptor.registerMBean(DefaultMBeanServerInterceptor.java:319)",
                "at com.sun.jmx.mbeanserver.JmxMBeanServer.registerMBean(JmxMBeanServer.java:522)",
                "at org.apache.hadoop.metrics2.util.MBeans.register(MBeans.java:66)",
                "at org.apache.hadoop.metrics2.impl.MetricsSourceAdapter.startMBeans(MetricsSourceAdapter.java:222)",
                "at org.apache.hadoop.metrics2.impl.MetricsSourceAdapter.start(MetricsSourceAdapter.java:100)",
                "at org.apache.hadoop.metrics2.impl.MetricsSystemImpl.registerSource(MetricsSystemImpl.java:268)",
                "at org.apache.hadoop.metrics2.impl.MetricsSystemImpl.register(MetricsSystemImpl.java:233)",
                "at org.apache.hadoop.ipc.DecayRpcScheduler$MetricsProxy.registerMetrics2Source(DecayRpcScheduler.java:709)",
                "at org.apache.hadoop.ipc.DecayRpcScheduler$MetricsProxy.<init>(DecayRpcScheduler.java:685)",
                "at org.apache.hadoop.ipc.DecayRpcScheduler$MetricsProxy.getInstance(DecayRpcScheduler.java:693)",
                "at org.apache.hadoop.ipc.DecayRpcScheduler.<init>(DecayRpcScheduler.java:236)",
                "at sun.reflect.NativeConstructorAccessorImpl.newInstance0(Native Method)",
                "at sun.reflect.NativeConstructorAccessorImpl.newInstance(NativeConstructorAccessorImpl.java:62)",
                "at sun.reflect.DelegatingConstructorAccessorImpl.newInstance(DelegatingConstructorAccessorImpl.java:45)",
                "at java.lang.reflect.Constructor.newInstance(Constructor.java:423)",
                "at org.apache.hadoop.ipc.CallQueueManager.createScheduler(CallQueueManager.java:102)",
                "at org.apache.hadoop.ipc.CallQueueManager.<init>(CallQueueManager.java:76)",
                "at org.apache.hadoop.ipc.Server.<init>(Server.java:2612)",
                "at org.apache.hadoop.ipc.RPC$Server.<init>(RPC.java:958)",
                "at org.apache.hadoop.ipc.ProtobufRpcEngine$Server.<init>(ProtobufRpcEngine.java:374)",
                "at org.apache.hadoop.ipc.ProtobufRpcEngine.getServer(ProtobufRpcEngine.java:349)",
                "at org.apache.hadoop.ipc.RPC$Builder.build(RPC.java:800)",
                "at org.apache.hadoop.hdfs.server.namenode.NameNodeRpcServer.<init>(NameNodeRpcServer.java:415)",
                "at org.apache.hadoop.hdfs.server.namenode.NameNode.createRpcServer(NameNode.java:755)",
                "at org.apache.hadoop.hdfs.server.namenode.NameNode.initialize(NameNode.java:697)",
                "at org.apache.hadoop.hdfs.server.namenode.NameNode.<init>(NameNode.java:905)",
                "at org.apache.hadoop.hdfs.server.namenode.NameNode.<init>(NameNode.java:884)",
                "at org.apache.hadoop.hdfs.server.namenode.NameNode.createNameNode(NameNode.java:1610)",
                "at org.apache.hadoop.hdfs.server.namenode.NameNode.main(NameNode.java:1678)"
            ],
            "RootCause": "The NullPointerException is likely caused by an uninitialized or null reference in the MetricsProxy class when attempting to access metrics data. This could be due to a failure in the initialization sequence of the MetricsSourceAdapter or related components.",
            "StepsToReproduce": [
                "Start the Hadoop HDFS NameNode.",
                "Monitor the logs for any initialization errors.",
                "Observe the stack trace generated during the startup process."
            ],
            "ExpectedBehavior": "The NameNode should initialize successfully without throwing any exceptions, and metrics should be registered correctly.",
            "ObservedBehavior": "The NameNode fails to initialize due to a NullPointerException, preventing the Hadoop HDFS from starting properly.",
            "Suggestions": "Investigate the initialization sequence of the MetricsProxy and MetricsSourceAdapter classes. Ensure that all necessary dependencies are properly initialized before they are accessed. Consider adding null checks or initializing default values to prevent NullPointerExceptions."
        }
    },
    {
        "filename": "HADOOP-8110.json",
        "creation_time": "2012-02-24T18:49:27.000+0000",
        "bug_report": {
            "Title": "JUnit Assertion Failure in TestTrash.trashShell",
            "Description": "The JUnit test for the trashShell method in the TestTrash class is failing due to an assertion error. The test expected the return value to be 0, indicating no files were present in the trash, but it returned 1, suggesting that there is at least one file in the trash.",
            "StackTrace": [
                "junit.framework.AssertionFailedError: -expunge failed expected:<0> but was:<1>",
                "at junit.framework.Assert.fail(Assert.java:47)",
                "at junit.framework.Assert.failNotEquals(Assert.java:283)",
                "at junit.framework.Assert.assertEquals(Assert.java:64)",
                "at junit.framework.Assert.assertEquals(Assert.java:195)",
                "at org.apache.hadoop.fs.TestTrash.trashShell(TestTrash.java:322)",
                "at org.apache.hadoop.fs.viewfs.TestViewFsTrash.testTrash(TestViewFsTrash.java:73)"
            ],
            "RootCause": "The trashShell method is not correctly expunging files from the trash, leading to an unexpected count of files remaining. This could be due to improper handling of file deletion or incorrect state management within the method.",
            "StepsToReproduce": [
                "Run the JUnit test suite that includes TestTrash.",
                "Ensure that the environment is set up with the necessary Hadoop configurations.",
                "Observe the output of the test case for TestTrash.trashShell."
            ],
            "ExpectedBehavior": "The trashShell method should return 0, indicating that there are no files left in the trash after the expunge operation.",
            "ObservedBehavior": "The trashShell method returned 1, indicating that there is at least one file remaining in the trash, which contradicts the expected behavior.",
            "Suggestions": "Investigate the implementation of the trashShell method in the TestTrash class. Check for any conditions that may prevent files from being deleted from the trash. Additionally, review the setup of the test case to ensure that it accurately reflects the expected state before the test runs."
        }
    },
    {
        "filename": "HADOOP-11400.json",
        "creation_time": "2014-12-12T10:05:52.000+0000",
        "bug_report": {
            "Title": "MetricsException: Error Flushing Metrics Due to SocketException",
            "Description": "The application encounters a MetricsException when attempting to flush metrics to the Graphite sink. The underlying cause is a SocketException indicating a broken pipe, suggesting that the connection to the socket was lost during the write operation.",
            "StackTrace": [
                "org.apache.hadoop.metrics2.MetricsException: Error flushing metrics",
                "at org.apache.hadoop.metrics2.sink.GraphiteSinkFixed.flush(GraphiteSinkFixed.java:120)",
                "at org.apache.hadoop.metrics2.impl.MetricsSinkAdapter.consume(MetricsSinkAdapter.java:184)",
                "at org.apache.hadoop.metrics2.impl.MetricsSinkAdapter.consume(MetricsSinkAdapter.java:43)",
                "at org.apache.hadoop.metrics2.impl.SinkQueue.consumeAll(SinkQueue.java:87)",
                "at org.apache.hadoop.metrics2.impl.MetricsSinkAdapter.publishMetricsFromQueue(MetricsSinkAdapter.java:129)",
                "at org.apache.hadoop.metrics2.impl.MetricsSinkAdapter$1.run(MetricsSinkAdapter.java:88)",
                "Caused by: java.net.SocketException: Broken pipe",
                "at java.net.SocketOutputStream.socketWrite0(Native Method)",
                "at java.net.SocketOutputStream.socketWrite(SocketOutputStream.java:113)",
                "at java.net.SocketOutputStream.write(SocketOutputStream.java:159)",
                "at sun.nio.cs.StreamEncoder.writeBytes(StreamEncoder.java:221)",
                "at sun.nio.cs.StreamEncoder.implFlushBuffer(StreamEncoder.java:291)",
                "at sun.nio.cs.StreamEncoder.implFlush(StreamEncoder.java:295)",
                "at sun.nio.cs.StreamEncoder.flush(StreamEncoder.java:141)",
                "at java.io.OutputStreamWriter.flush(OutputStreamWriter.java:229)",
                "at org.apache.hadoop.metrics2.sink.GraphiteSinkFixed.flush(GraphiteSinkFixed.java:118)"
            ],
            "RootCause": "The SocketException: Broken pipe indicates that the connection to the socket was lost while attempting to write data, likely due to network issues or the server closing the connection unexpectedly.",
            "StepsToReproduce": [
                "Configure the application to send metrics to a Graphite server.",
                "Ensure the Graphite server is running and accessible.",
                "Simulate network instability or shut down the Graphite server while the application is running.",
                "Observe the application logs for MetricsException errors."
            ],
            "ExpectedBehavior": "The application should successfully flush metrics to the Graphite sink without encountering any exceptions.",
            "ObservedBehavior": "The application throws a MetricsException indicating an error flushing metrics due to a SocketException.",
            "Suggestions": "Check the network connection between the application and the Graphite server. Ensure that the Graphite server is running and can accept connections. Consider implementing retry logic in the metrics flushing process to handle transient network issues."
        }
    },
    {
        "filename": "HADOOP-9865.json",
        "creation_time": "2013-08-12T23:22:58.000+0000",
        "bug_report": {
            "Title": "HadoopIllegalArgumentException: Path is relative",
            "Description": "An exception is thrown when a relative path is passed to a method that requires an absolute path in the Hadoop framework. This issue occurs during the container launch process in the YARN NodeManager.",
            "StackTrace": [
                "org.apache.hadoop.HadoopIllegalArgumentException: Path is relative",
                "at org.apache.hadoop.fs.Path.checkNotRelative(Path.java:74)",
                "at org.apache.hadoop.fs.FileContext.getFSofPath(FileContext.java:304)",
                "at org.apache.hadoop.fs.Globber.schemeFromPath(Globber.java:107)",
                "at org.apache.hadoop.fs.Globber.glob(Globber.java:128)",
                "at org.apache.hadoop.fs.FileContext$Util.globStatus(FileContext.java:1908)",
                "at org.apache.hadoop.fs.FileUtil.createJarWithClassPath(FileUtil.java:1247)",
                "at org.apache.hadoop.yarn.server.nodemanager.containermanager.launcher.ContainerLaunch.sanitizeEnv(ContainerLaunch.java:679)",
                "at org.apache.hadoop.yarn.server.nodemanager.containermanager.launcher.ContainerLaunch.call(ContainerLaunch.java:232)",
                "at org.apache.hadoop.yarn.server.nodemanager.containermanager.launcher.ContainerLaunch.call(ContainerLaunch.java:1)",
                "at java.util.concurrent.FutureTask$Sync.innerRun(FutureTask.java:303)",
                "at java.util.concurrent.FutureTask.run(FutureTask.java:138)",
                "at java.util.concurrent.ThreadPoolExecutor$Worker.runTask(ThreadPoolExecutor.java:886)",
                "at java.util.concurrent.ThreadPoolExecutor$Worker.run(ThreadPoolExecutor.java:908)",
                "at java.lang.Thread.run(Thread.java:662)"
            ],
            "RootCause": "A relative path was passed to a method that requires an absolute path, leading to the HadoopIllegalArgumentException.",
            "StepsToReproduce": [
                "Configure a YARN application with a relative path for the classpath or jar file.",
                "Attempt to launch the application using the YARN NodeManager.",
                "Observe the exception thrown in the logs."
            ],
            "ExpectedBehavior": "The application should launch successfully without throwing an exception related to path resolution.",
            "ObservedBehavior": "The application fails to launch, throwing a HadoopIllegalArgumentException indicating that the path is relative.",
            "Suggestions": "Ensure that all paths provided to the YARN NodeManager are absolute paths. Review the configuration files and code where paths are defined to confirm they are absolute."
        }
    },
    {
        "filename": "HADOOP-9977.json",
        "creation_time": "2013-09-17T22:11:54.000+0000",
        "bug_report": {
            "Title": "IOException due to UnrecoverableKeyException in Hadoop HttpServer Initialization",
            "Description": "The application encounters an IOException caused by an UnrecoverableKeyException when initializing the HttpServer in Hadoop. This prevents the NameNode from starting its HTTP server, which is critical for its operation.",
            "StackTrace": [
                "java.io.IOException: java.security.UnrecoverableKeyException: Cannot recover key",
                "at org.apache.hadoop.http.HttpServer.<init>(HttpServer.java:222)",
                "at org.apache.hadoop.http.HttpServer.<init>(HttpServer.java:174)",
                "at org.apache.hadoop.hdfs.server.namenode.NameNodeHttpServer$1.<init>(NameNodeHttpServer.java:76)",
                "at org.apache.hadoop.hdfs.server.namenode.NameNodeHttpServer.start(NameNodeHttpServer.java:74)",
                "at org.apache.hadoop.hdfs.server.namenode.NameNode.startHttpServer(NameNode.java:626)",
                "at org.apache.hadoop.hdfs.server.namenode.NameNode.initialize(NameNode.java:488)",
                "at org.apache.hadoop.hdfs.server.namenode.NameNode.<init>(NameNode.java:684)",
                "at org.apache.hadoop.hdfs.server.namenode.NameNode.<init>(NameNode.java:669)",
                "at org.apache.hadoop.hdfs.server.namenode.NameNode.createNameNode(NameNode.java:1254)",
                "at org.apache.hadoop.hdfs.server.namenode.NameNode.main(NameNode.java:1320)",
                "Caused by: java.security.UnrecoverableKeyException: Cannot recover key",
                "at sun.security.provider.KeyProtector.recover(KeyProtector.java:328)",
                "at sun.security.provider.JavaKeyStore.engineGetKey(JavaKeyStore.java:138)",
                "at sun.security.provider.JavaKeyStore$JKS.engineGetKey(JavaKeyStore.java:55)",
                "at java.security.KeyStore.getKey(KeyStore.java:792)",
                "at sun.security.ssl.SunX509KeyManagerImpl.<init>(SunX509KeyManagerImpl.java:131)",
                "at sun.security.ssl.KeyManagerFactoryImpl$SunX509.engineInit(KeyManagerFactoryImpl.java:68)",
                "at javax.net.ssl.KeyManagerFactory.init(KeyManagerFactory.java:259)",
                "at org.apache.hadoop.security.ssl.FileBasedKeyStoresFactory.init(FileBasedKeyStoresFactory.java:170)",
                "at org.apache.hadoop.security.ssl.SSLFactory.init(SSLFactory.java:121)",
                "at org.apache.hadoop.http.HttpServer.<init>(HttpServer.java:220)"
            ],
            "RootCause": "The UnrecoverableKeyException indicates that the application is unable to recover a key from the keystore, likely due to an incorrect password, the key not being found, or issues with keystore accessibility.",
            "StepsToReproduce": [
                "Start the Hadoop NameNode service.",
                "Ensure that the keystore file is configured correctly in the Hadoop configuration.",
                "Attempt to access the NameNode HTTP server."
            ],
            "ExpectedBehavior": "The NameNode should start successfully, and the HTTP server should be accessible without any exceptions.",
            "ObservedBehavior": "The NameNode fails to start its HTTP server, throwing an IOException due to an UnrecoverableKeyException.",
            "Suggestions": "Verify the keystore password and ensure it is correct. Check that the key exists in the keystore and that the keystore file is accessible by the application. If necessary, regenerate the keystore and update the configuration accordingly."
        }
    },
    {
        "filename": "HADOOP-12611.json",
        "creation_time": "2015-12-01T17:14:38.000+0000",
        "bug_report": {
            "Title": "AssertionError and IllegalStateException in ZKSignerSecretProvider Tests",
            "Description": "The test case 'testMultipleInit' in 'TestZKSignerSecretProvider' is failing due to an AssertionError indicating that a value expected to be null is not. Additionally, an IllegalStateException is thrown when attempting to call a method on an uninitialized instance of 'CuratorFrameworkImpl'.",
            "StackTrace": [
                "java.lang.AssertionError: expected null, but was:<[B@142bad79>",
                "at org.junit.Assert.fail(Assert.java:88)",
                "at org.junit.Assert.failNotNull(Assert.java:664)",
                "at org.junit.Assert.assertNull(Assert.java:646)",
                "at org.junit.Assert.assertNull(Assert.java:656)",
                "at org.apache.hadoop.security.authentication.util.TestZKSignerSecretProvider.testMultipleInit(TestZKSignerSecretProvider.java:149)",
                "java.lang.IllegalStateException: instance must be started before calling this method",
                "at com.google.common.base.Preconditions.checkState(Preconditions.java:145)",
                "at org.apache.curator.framework.imps.CuratorFrameworkImpl.getData(CuratorFrameworkImpl.java:363)",
                "at org.apache.hadoop.security.authentication.util.ZKSignerSecretProvider.pullFromZK(ZKSignerSecretProvider.java:341)",
                "at org.apache.hadoop.security.authentication.util.ZKSignerSecretProvider.rollSecret(ZKSignerSecretProvider.java:264)",
                "at org.apache.hadoop.security.authentication.util.ZKSignerSecretProvider$$EnhancerByMockitoWithCGLIB$$575f06d8.CGLIB$rollSecret$2(<generated>)",
                "at org.apache.hadoop.security.authentication.util.ZKSignerSecretProvider$$EnhancerByMockitoWithCGLIB$$575f06d8$$FastClassByMockitoWithCGLIB$$6f94a716.invoke(<generated>)",
                "at org.mockito.cglib.proxy.MethodProxy.invokeSuper(MethodProxy.java:216)",
                "at org.mockito.internal.creation.AbstractMockitoMethodProxy.invokeSuper(AbstractMockitoMethodProxy.java:10)",
                "at org.mockito.internal.invocation.realmethod.CGLIBProxyRealMethod.invoke(CGLIBProxyRealMethod.java:22)",
                "at org.mockito.internal.invocation.realmethod.FilteredCGLIBProxyRealMethod.invoke(FilteredCGLIBProxyRealMethod.java:27)",
                "at org.mockito.internal.invocation.Invocation.callRealMethod(Invocation.java:211)",
                "at org.mockito.internal.stubbing.answers.CallsRealMethods.answer(CallsRealMethods.java:36)",
                "at org.mockito.internal.MockHandler.handle(MockHandler.java:99)",
                "at org.mockito.internal.creation.MethodInterceptorFilter.intercept(MethodInterceptorFilter.java:47)",
                "at org.apache.hadoop.security.authentication.util.ZKSignerSecretProvider$$EnhancerByMockitoWithCGLIB$$575f06d8.rollSecret(<generated>)",
                "at org.apache.hadoop.security.authentication.util.RolloverSignerSecretProvider$1.run(RolloverSignerSecretProvider.java:97)",
                "at java.util.concurrent.Executors$RunnableAdapter.call(Executors.java:471)",
                "at java.util.concurrent.FutureTask.runAndReset(FutureTask.java:304)",
                "at java.util.concurrent.ScheduledThreadPoolExecutor$ScheduledFutureTask.access$301(ScheduledThreadPoolExecutor.java:178)",
                "at java.util.concurrent.ScheduledThreadPoolExecutor$ScheduledFutureTask.run(ScheduledThreadPoolExecutor.java:293)",
                "at java.util.concurrent.ThreadPoolExecutor.runWorker(ThreadPoolExecutor.java:1145)",
                "at java.util.concurrent.ThreadPoolExecutor$Worker.run(ThreadPoolExecutor.java:615)",
                "at java.lang.Thread.run(Thread.java:745)"
            ],
            "RootCause": "The test case is failing because the method 'rollSecret' is being called on an uninitialized instance of 'CuratorFrameworkImpl', leading to an IllegalStateException. This is likely due to the instance not being properly started before the method call, which is a prerequisite for its execution.",
            "StepsToReproduce": [
                "Run the test suite containing 'TestZKSignerSecretProvider'.",
                "Observe the failure in the 'testMultipleInit' test case."
            ],
            "ExpectedBehavior": "The 'testMultipleInit' test case should pass without any assertion errors or exceptions, indicating that the expected values are correctly initialized and the methods are called on properly started instances.",
            "ObservedBehavior": "The test case fails with an AssertionError indicating a non-null value where null was expected, and an IllegalStateException indicating that a method was called on an uninitialized instance.",
            "Suggestions": "Ensure that the instance of 'CuratorFrameworkImpl' is properly initialized and started before invoking any methods on it. Review the setup code in 'TestZKSignerSecretProvider' to confirm that all necessary initializations are performed before the test runs."
        }
    },
    {
        "filename": "HADOOP-10142.json",
        "creation_time": "2013-12-03T06:33:32.000+0000",
        "bug_report": {
            "Title": "User Not Found Exception in Hadoop Shell Command",
            "Description": "The application throws an ExitCodeException indicating that the user 'dr.who' does not exist when attempting to retrieve Unix group information. This issue arises during the execution of a shell command within the Hadoop framework.",
            "StackTrace": [
                "org.apache.hadoop.util.Shell$ExitCodeException: id: dr.who: No such user",
                "at org.apache.hadoop.util.Shell.runCommand(Shell.java:504)",
                "at org.apache.hadoop.util.Shell.run(Shell.java:417)",
                "at org.apache.hadoop.util.Shell$ShellCommandExecutor.execute(Shell.java:636)",
                "at org.apache.hadoop.util.Shell.execCommand(Shell.java:725)",
                "at org.apache.hadoop.util.Shell.execCommand(Shell.java:708)",
                "at org.apache.hadoop.security.ShellBasedUnixGroupsMapping.getUnixGroups(ShellBasedUnixGroupsMapping.java:83)",
                "at org.apache.hadoop.security.ShellBasedUnixGroupsMapping.getGroups(ShellBasedUnixGroupsMapping.java:52)",
                "at org.apache.hadoop.security.JniBasedUnixGroupsMappingWithFallback.getGroups(JniBasedUnixGroupsMappingWithFallback.java:50)",
                "at org.apache.hadoop.security.Groups.getGroups(Groups.java:95)",
                "at org.apache.hadoop.security.UserGroupInformation.getGroupNames(UserGroupInformation.java:1376)",
                "at org.apache.hadoop.hdfs.server.namenode.FSPermissionChecker.<init>(FSPermissionChecker.java:63)",
                "at org.apache.hadoop.hdfs.server.namenode.FSNamesystem.getPermissionChecker(FSNamesystem.java:3228)",
                "at org.apache.hadoop.hdfs.server.namenode.FSNamesystem.getListingInt(FSNamesystem.java:4063)",
                "at org.apache.hadoop.hdfs.server.namenode.FSNamesystem.getListing(FSNamesystem.java:4052)",
                "at org.apache.hadoop.hdfs.server.namenode.NameNodeRpcServer.getListing(NameNodeRpcServer.java:748)",
                "at org.apache.hadoop.hdfs.server.namenode.web.resources.NamenodeWebHdfsMethods.getDirectoryListing(NamenodeWebHdfsMethods.java:715)",
                "at org.apache.hadoop.hdfs.server.namenode.web.resources.NamenodeWebHdfsMethods.getListingStream(NamenodeWebHdfsMethods.java:727)",
                "at org.apache.hadoop.hdfs.server.namenode.web.resources.NamenodeWebHdfsMethods.get(NamenodeWebHdfsMethods.java:675)",
                "at org.apache.hadoop.hdfs.server.namenode.web.resources.NamenodeWebHdfsMethods.access$400(NamenodeWebHdfsMethods.java:114)",
                "at org.apache.hadoop.hdfs.server.namenode.web.resources.NamenodeWebHdfsMethods$3.run(NamenodeWebHdfsMethods.java:623)",
                "at org.apache.hadoop.hdfs.server.namenode.web.resources.NamenodeWebHdfsMethods$3.run(NamenodeWebHdfsMethods.java:618)",
                "at java.security.AccessController.doPrivileged(Native Method)",
                "at javax.security.auth.Subject.doAs(Subject.java:396)",
                "at org.apache.hadoop.security.UserGroupInformation.doAs(UserGroupInformation.java:1515)",
                "at org.apache.hadoop.hdfs.server.namenode.web.resources.NamenodeWebHdfsMethods.get(NamenodeWebHdfsMethods.java:618)",
                "at org.apache.hadoop.hdfs.server.namenode.web.resources.NamenodeWebHdfsMethods.getRoot(NamenodeWebHdfsMethods.java:586)",
                "at sun.reflect.NativeMethodAccessorImpl.invoke0(Native Method)",
                "at sun.reflect.NativeMethodAccessorImpl.invoke(NativeMethodAccessorImpl.java:39)",
                "at sun.reflect.DelegatingMethodAccessorImpl.invoke(DelegatingMethodAccessorImpl.java:25)",
                "at java.lang.reflect.Method.invoke(Method.java:597)",
                "at com.sun.jersey.spi.container.JavaMethodInvokerFactory$1.invoke(JavaMethodInvokerFactory.java:60)",
                "at com.sun.jersey.server.impl.model.method.dispatch.AbstractResourceMethodDispatchProvider$ResponseOutInvoker._dispatch(AbstractResourceMethodDispatchProvider.java:205)",
                "at com.sun.jersey.server.impl.model.method.dispatch.ResourceJavaMethodDispatcher.dispatch(ResourceJavaMethodDispatcher.java:75)",
                "at com.sun.jersey.server.impl.uri.rules.HttpMethodRule.accept(HttpMethodRule.java:288)",
                "at com.sun.jersey.server.impl.uri.rules.ResourceClassRule.accept(ResourceClassRule.java:108)",
                "at com.sun.jersey.server.impl.uri.rules.RightHandPathRule.accept(ResourceClassRule.java:147)",
                "at com.sun.jersey.server.impl.uri.rules.RootResourceClassesRule.accept(ResourceClassRule.java:84)",
                "at com.sun.jersey.server.impl.application.WebApplicationImpl._handleRequest(WebApplicationImpl.java:1469)",
                "at com.sun.jersey.server.impl.application.WebApplicationImpl._handleRequest(WebApplicationImpl.java:1400)",
                "at com.sun.jersey.server.impl.application.WebApplicationImpl.handleRequest(WebApplicationImpl.java:1349)",
                "at com.sun.jersey.server.impl.application.WebApplicationImpl.handleRequest(WebApplicationImpl.java:1339)",
                "at com.sun.jersey.spi.container.servlet.WebComponent.service(WebComponent.java:416)",
                "at com.sun.jersey.spi.container.servlet.ServletContainer.service(ServletContainer.java:537)",
                "at com.sun.jersey.spi.container.servlet.ServletContainer.service(ServletContainer.java:699)",
                "at javax.servlet.http.HttpServlet.service(HttpServlet.java:820)",
                "at org.mortbay.jetty.servlet.ServletHolder.handle(ServletHolder.java:511)",
                "at org.mortbay.jetty.servlet.ServletHandler$CachedChain.doFilter(ServletHandler.java:1221)",
                "at org.apache.hadoop.security.authentication.server.AuthenticationFilter.doFilter(AuthenticationFilter.java:384)",
                "at org.apache.hadoop.hdfs.web.AuthFilter.doFilter(AuthFilter.java:85)",
                "at org.mortbay.jetty.servlet.ServletHandler$CachedChain.doFilter(ServletHandler.java:1212)",
                "at org.apache.hadoop.http.HttpServer$QuotingInputFilter.doFilter(HttpServer.java:1310)",
                "at org.mortbay.jetty.servlet.ServletHandler$CachedChain.doFilter(ServletHandler.java:1212)",
                "at org.apache.hadoop.http.NoCacheFilter.doFilter(NoCacheFilter.java:45)",
                "at org.mortbay.jetty.servlet.ServletHandler$CachedChain.doFilter(ServletHandler.java:1212)",
                "at org.apache.hadoop.http.NoCacheFilter.doFilter(NoCacheFilter.java:45)",
                "at org.mortbay.jetty.servlet.ServletHandler.doFilter(ServletHandler.java:1212)",
                "at org.mortbay.jetty.servlet.ServletHandler.handle(ServletHandler.java:399)",
                "at org.mortbay.jetty.security.SecurityHandler.handle(SecurityHandler.java:216)",
                "at org.mortbay.jetty.servlet.SessionHandler.handle(SessionHandler.java:182)",
                "at org.mortbay.jetty.handler.ContextHandler.handle(ContextHandler.java:766)",
                "at org.mortbay.jetty.webapp.WebAppContext.handle(WebAppContext.java:450)",
                "at org.mortbay.jetty.handler.ContextHandlerCollection.handle(ContextHandlerCollection.java:230)",
                "at org.mortbay.jetty.handler.HandlerWrapper.handle(HandlerWrapper.java:152)",
                "at org.mortbay.jetty.Server.handle(Server.java:326)",
                "at org.mortbay.jetty.HttpConnection.handleRequest(HttpConnection.java:542)",
                "at org.mortbay.jetty.HttpConnection$RequestHandler.headerComplete(HttpConnection.java:928)",
                "at org.mortbay.jetty.HttpParser.parseNext(HttpParser.java:549)",
                "at org.mortbay.jetty.HttpParser.parseAvailable(HttpParser.java:212)",
                "at org.mortbay.jetty.HttpConnection.handle(HttpConnection.java:404)",
                "at org.mortbay.io.nio.SelectChannelEndPoint.run(SelectChannelEndPoint.java:410)",
                "at org.mortbay.thread.QueuedThreadPool$PoolThread.run(QueuedThreadPool.java:582)"
            ],
            "RootCause": "The user 'dr.who' does not exist on the system, leading to a failure in retrieving Unix group information.",
            "StepsToReproduce": [
                "Attempt to execute a command that requires Unix group information for the user 'dr.who'.",
                "Ensure that the Hadoop environment is set up correctly.",
                "Observe the logs for the ExitCodeException."
            ],
            "ExpectedBehavior": "The system should retrieve the Unix group information for the specified user without errors.",
            "ObservedBehavior": "An ExitCodeException is thrown indicating that the user 'dr.who' does not exist.",
            "Suggestions": "Ensure that the user 'dr.who' exists on the system. If the user is not required, modify the code to handle the exception gracefully."
        }
    },
    {
        "filename": "HADOOP-14727.json",
        "creation_time": "2017-08-02T21:56:38.000+0000",
        "bug_report": {
            "Title": "HDFS Block Reader Exception",
            "Description": "An exception occurs when attempting to read a block from HDFS, indicating potential network issues, configuration errors, or data corruption.",
            "StackTrace": [
                "java.lang.Exception: test",
                "at org.apache.hadoop.hdfs.client.impl.BlockReaderFactory.getRemoteBlockReaderFromTcp(BlockReaderFactory.java:745)",
                "at org.apache.hadoop.hdfs.client.impl.BlockReaderFactory.build(BlockReaderFactory.java:385)",
                "at org.apache.hadoop.hdfs.DFSInputStream.getBlockReader(DFSInputStream.java:636)",
                "at org.apache.hadoop.hdfs.DFSInputStream.blockSeekTo(DFSInputStream.java:566)",
                "at org.apache.hadoop.hdfs.DFSInputStream.readWithStrategy(DFSInputStream.java:749)",
                "at org.apache.hadoop.hdfs.DFSInputStream.read(DFSInputStream.java:807)",
                "at java.io.DataInputStream.read(DataInputStream.java:149)",
                "at com.ctc.wstx.io.StreamBootstrapper.ensureLoaded(StreamBootstrapper.java:482)",
                "at com.ctc.wstx.io.StreamBootstrapper.resolveStreamEncoding(StreamBootstrapper.java:306)",
                "at com.ctc.wstx.io.StreamBootstrapper.bootstrapInput(StreamBootstrapper.java:167)",
                "at com.ctc.wstx.stax.WstxInputFactory.doCreateSR(WstxInputFactory.java:573)",
                "at com.ctc.wstx.stax.WstxInputFactory.createSR(WstxInputFactory.java:633)",
                "at com.ctc.wstx.stax.WstxInputFactory.createSR(WstxInputFactory.java:647)",
                "at com.ctc.wstx.stax.WstxInputFactory.createXMLStreamReader(WstxInputFactory.java:366)",
                "at org.apache.hadoop.conf.Configuration.parse(Configuration.java:2649)",
                "at org.apache.hadoop.conf.Configuration.loadResource(Configuration.java:2697)",
                "at org.apache.hadoop.conf.Configuration.loadResources(Configuration.java:2662)",
                "at org.apache.hadoop.conf.Configuration.getProps(Configuration.java:2545)",
                "at org.apache.hadoop.conf.Configuration.get(Configuration.java:1076)",
                "at org.apache.hadoop.conf.Configuration.getTrimmed(Configuration.java:1126)",
                "at org.apache.hadoop.conf.Configuration.getInt(Configuration.java:1344)",
                "at org.apache.hadoop.mapreduce.counters.Limits.init(Limits.java:45)",
                "at org.apache.hadoop.mapreduce.counters.Limits.reset(Limits.java:130)",
                "at org.apache.hadoop.mapreduce.v2.hs.CompletedJob.loadFullHistoryData(CompletedJob.java:363)",
                "at org.apache.hadoop.mapreduce.v2.hs.CompletedJob.<init>(CompletedJob.java:105)",
                "at org.apache.hadoop.mapreduce.v2.hs.HistoryFileManager$HistoryFileInfo.loadJob(HistoryFileManager.java:473)",
                "at org.apache.hadoop.mapreduce.v2.hs.CachedHistoryStorage.loadJob(CachedHistoryStorage.java:180)",
                "at org.apache.hadoop.mapreduce.v2.hs.CachedHistoryStorage.access$000(CachedHistoryStorage.java:52)",
                "at org.apache.hadoop.mapreduce.v2.hs.CachedHistoryStorage$1.load(CachedHistoryStorage.java:103)",
                "at org.apache.hadoop.mapreduce.v2.hs.CachedHistoryStorage$1.load(CachedHistoryStorage.java:100)",
                "at com.google.common.cache.LocalCache$LoadingValueReference.loadFuture(LocalCache.java:3568)",
                "at com.google.common.cache.LocalCache$Segment.loadSync(LocalCache.java:2350)",
                "at com.google.common.cache.LocalCache$Segment.lockedGetOrLoad(LocalCache.java:2313)",
                "at com.google.common.cache.LocalCache$Segment.get(LocalCache.java:2228)",
                "at com.google.common.cache.LocalCache.get(LocalCache.java:3965)",
                "at com.google.common.cache.LocalCache.getOrLoad(LocalCache.java:3969)",
                "at com.google.common.cache.LocalCache$LocalManualCache.get(LocalCache.java:4829)",
                "at com.google.common.cache.LocalCache$LocalManualCache.getUnchecked(LocalCache.java:4834)",
                "at org.apache.hadoop.mapreduce.v2.hs.CachedHistoryStorage.getFullJob(CachedHistoryStorage.java:193)",
                "at org.apache.hadoop.mapreduce.v2.hs.JobHistory.getJob(JobHistory.java:220)",
                "at org.apache.hadoop.mapreduce.v2.app.webapp.AppController.requireJob(AppController.java:416)",
                "at org.apache.hadoop.mapreduce.v2.app.webapp.AppController.attempts(AppController.java:277)",
                "at org.apache.hadoop.mapreduce.v2.hs.webapp.HsController.attempts(HsController.java:152)",
                "at sun.reflect.NativeMethodAccessorImpl.invoke0(Native Method)",
                "at sun.reflect.NativeMethodAccessorImpl.invoke(NativeMethodAccessorImpl.java:62)",
                "at sun.reflect.DelegatingMethodAccessorImpl.invoke(DelegatingMethodAccessorImpl.java:43)",
                "at java.lang.reflect.Method.invoke(Method.java:498)",
                "at org.apache.hadoop.yarn.webapp.Dispatcher.service(Dispatcher.java:162)",
                "at javax.servlet.http.HttpServlet.service(HttpServlet.java:790)",
                "at com.google.inject.servlet.ServletDefinition.doServiceImpl(ServletDefinition.java:287)",
                "at com.google.inject.servlet.ServletDefinition.doService(ServletDefinition.java:277)",
                "at com.google.inject.servlet.ServletDefinition.service(ServletDefinition.java:182)",
                "at com.google.inject.servlet.ManagedServletPipeline.service(ManagedServletPipeline.java:91)",
                "at com.google.inject.servlet.FilterChainInvocation.doFilter(FilterChainInvocation.java:85)",
                "at com.sun.jersey.spi.container.servlet.ServletContainer.doFilter(ServletContainer.java:941)",
                "at com.sun.jersey.spi.container.servlet.ServletContainer.doFilter(ServletContainer.java:875)",
                "at com.sun.jersey.spi.container.servlet.ServletContainer.doFilter(ServletContainer.java:829)",
                "at com.google.inject.servlet.FilterChainInvocation.doFilter(FilterChainInvocation.java:82)",
                "at com.google.inject.servlet.ManagedFilterPipeline.dispatch(ManagedFilterPipeline.java:119)",
                "at com.google.inject.servlet.GuiceFilter$1.call(GuiceFilter.java:133)",
                "at com.google.inject.servlet.GuiceFilter$1.call(GuiceFilter.java:130)",
                "at com.google.inject.servlet.GuiceFilter$Context.call(GuiceFilter$1.call(GuiceFilter.java:203)",
                "at com.google.inject.servlet.GuiceFilter.doFilter(GuiceFilter.java:130)",
                "at org.eclipse.jetty.servlet.ServletHandler$CachedChain.doFilter(ServletHandler.java:1759)",
                "at org.apache.hadoop.security.http.XFrameOptionsFilter.doFilter(XFrameOptionsFilter.java:57)",
                "at org.eclipse.jetty.servlet.ServletHandler$CachedChain.doFilter(ServletHandler.java:1759)",
                "at org.apache.hadoop.http.lib.StaticUserWebFilter$StaticUserFilter.doFilter(StaticUserWebFilter.java:109)",
                "at org.eclipse.jetty.servlet.ServletHandler$CachedChain.doFilter(ServletHandler.java:1759)",
                "at org.eclipse.jetty.servlet.ServletHandler.doHandle(ServletHandler.java:582)",
                "at org.eclipse.jetty.server.handler.ScopedHandler.handle(ScopedHandler.java:143)",
                "at org.eclipse.jetty.server.handler.HandlerCollection.handle(HandlerCollection.java:119)",
                "at org.eclipse.jetty.server.handler.HandlerWrapper.handle(HandlerWrapper.java:134)",
                "at org.eclipse.jetty.server.Server.handle(Server.java:534)",
                "at org.eclipse.jetty.server.HttpChannel.handle(HttpChannel.java:320)",
                "at org.eclipse.jetty.server.HttpConnection.onFillable(HttpConnection.java:251)",
                "at org.eclipse.jetty.io.AbstractConnection$ReadCallback.succeeded(AbstractConnection.java:283)",
                "at org.eclipse.jetty.io.FillInterest.fillable(FillInterest.java:108)",
                "at org.eclipse.jetty.io.SelectChannelEndPoint$2.run(SelectChannelEndPoint.java:93)",
                "at org.eclipse.jetty.util.thread.strategy.ExecuteProduceConsume.executeProduceConsume(ExecuteProduceConsume.java:303)",
                "at org.eclipse.jetty.util.thread.strategy.ExecuteProduceConsume.produceConsume(ExecuteProduceConsume.java:148)",
                "at org.eclipse.jetty.util.thread.strategy.ExecuteProduceConsume.run(ExecuteProduceConsume.java:136)",
                "at org.eclipse.jetty.util.thread.QueuedThreadPool.runJob(QueuedThreadPool.java:671)",
                "at org.eclipse.jetty.util.thread.QueuedThreadPool$2.run(QueuedThreadPool.java:589)",
                "at java.lang.Thread.run(Thread.java:748)"
            ],
            "RootCause": "The exception likely originates from network issues, configuration errors, or data corruption when attempting to read from HDFS.",
            "StepsToReproduce": [
                "Attempt to read a block from HDFS using the BlockReaderFactory.",
                "Ensure that the HDFS configuration is correctly set up.",
                "Check network connectivity to the HDFS nodes."
            ],
            "ExpectedBehavior": "The block should be read successfully from HDFS without any exceptions.",
            "ObservedBehavior": "An exception is thrown indicating a failure to read the block, potentially due to network or configuration issues.",
            "Suggestions": "Investigate Hadoop logs for any related errors, verify HDFS configuration settings, and check for network connectivity issues. Additionally, ensure that the data being read is not corrupted."
        }
    }
]